Workbook

Sheet Sheet1
A3: Count of ICAO24 Hex | B3: Column Labels
A4: Row Labels | B4: 46289 | C4: 46290 | D4: 46291 | E4: Grand Total
A5: N2016J | B5: 2 | C5: 1 | D5: 3 | E5: 6
A6: N2017J | B6: 2 | C6: 1 | D6: 3 | E6: 6
A7: N2029J | B7: 1 | C7: 3 | D7: 1 | E7: 5
A8: N2038J | B8: 3 | C8: 2 | D8: 1 | E8: 6
A9: N2039J | B9: 4 | C9: 2 | E9: 6
A10: N2043J | B10: 1 | C10: 3 | D10: 2 | E10: 6
A11: N2044J | B11: 3 | C11: 2 | D11: 1 | E11: 6
A12: N2047J | B12: 3 | C12: 2 | D12: 1 | E12: 6
A13: N2048J | B13: 3 | C13: 1 | D13: 3 | E13: 7
A14: N2084J | B14: 1 | C14: 1 | D14: 2 | E14: 4
A15: N2086J | C15: 3 | D15: 3 | E15: 6
A16: N2142J | B16: 3 | C16: 3 | D16: 1 | E16: 7
A17: N2151J | C17: 3 | D17: 1 | E17: 4
A18: N2156J | B18: 3 | C18: 1 | D18: 3 | E18: 7
A19: N2157J | B19: 2 | C19: 2 | D19: 1 | E19: 5
A20: N2165J | B20: 2 | C20: 3 | D20: 3 | E20: 8
A21: N2169J | B21: 1 | C21: 2 | D21: 2 | E21: 5
A22: N2180J | B22: 1 | C22: 3 | D22: 2 | E22: 6
A23: N2188J | B23: 2 | D23: 3 | E23: 5
A24: N2193J | C24: 2 | D24: 2 | E24: 4
A25: N2199J | B25: 3 | C25: 3 | D25: 2 | E25: 8
A26: N2205J | B26: 3 | C26: 2 | D26: 2 | E26: 7
A27: N3023J | B27: 4 | C27: 5 | E27: 9
A28: N3044J | B28: 1 | C28: 1 | D28: 4 | E28: 6
A29: N3058J | B29: 2 | C29: 4 | D29: 4 | E29: 10
A30: N3062J | C30: 2 | D30: 2 | E30: 4
A31: N3065J | B31: 4 | C31: 4 | D31: 4 | E31: 12
A32: N3077J | B32: 5 | C32: 5 | D32: 5 | E32: 15
A33: N3085J | B33: 4 | C33: 4 | D33: 2 | E33: 10
A34: N3102J | B34: 2 | C34: 4 | D34: 3 | E34: 9
A35: N3104J | B35: 3 | C35: 1 | D35: 3 | E35: 7
A36: N3112J | B36: 4 | C36: 3 | D36: 3 | E36: 10
A37: N3113J | B37: 4 | C37: 4 | D37: 5 | E37: 13
A38: N3115J | B38: 4 | C38: 2 | D38: 5 | E38: 11
A39: N3118J | B39: 4 | C39: 4 | D39: 3 | E39: 11
A40: N3121J | B40: 4 | C40: 4 | D40: 4 | E40: 12
A41: N3123J | B41: 1 | C41: 5 | D41: 4 | E41: 10
A42: N3125J | B42: 4 | C42: 3 | D42: 4 | E42: 11
...

Sheet Flights
A1: Date (UTC) | B1: Flight No | C1: Callsign | D1: Origin | E1: Origin ICAO | F1: Destination | G1: Dest ICAO | H1: Departure (UTC) | I1: Arrival (UTC) | J1: Duration (min) | K1: Tail Number | L1: Aircraft Type | M1: ICAO Type | N1: Status | O1: ICAO24 Hex
A2: 46289 | B2: B6 2725 | C2: JBU2725 | D2: JFK | E2: KJFK | F2: TPA | G2: KTPA | H2: 46289 | I2: 46289.099 | J2: =ROUND((I2-H2)*1440,0) -> 143 | K2: N965JT | L2: A321 | M2: A321 | N2: Complete | O2: ad6f93
A3: 46289 | B3: B6 397 | C3: JBU397 | D3: BOS | E3: KBOS | F3: SEA | G3: KSEA | H3: 46289 | I3: 46289.235 | J3: =ROUND((I3-H3)*1440,0) -> 338 | K3: N971JT | L3: A321 | M3: A321 | N3: Complete | O3: ad8836
A4: 46289 | B4: B6 882 | C4: JBU882 | F4: JFK | G4: KJFK | H4: 46289.005 | I4: 46289.04 | J4: =ROUND((I4-H4)*1440,0) -> 50 | K4: N656JB | L4: A320 | M4: A320 | N4: Complete | O4: a8a3ce
A5: 46289 | B5: B6 1407 | C5: JBU1407 | D5: JFK | E5: KJFK | F5: CDG | G5: LFPG | H5: 46289.007 | I5: 46289.284 | J5: =ROUND((I5-H5)*1440,0) -> 399 | K5: N4073J | L5: A321neo | M5: A21N | N5: Landing inferred | O5: a4c96c
A6: 46289 | B6: B6 1860 | C6: JBU1860 | D6: PHL | E6: KPHL | F6: BOS | G6: KBOS | H6: 46289.008 | I6: 46289.044 | J6: =ROUND((I6-H6)*1440,0) -> 52 | K6: N3289J | L6: Unknown | N6: Complete | O6: a38fa4
A7: 46289 | B7: B6 706 | C7: JBU706 | D7: FLL | E7: KFLL | F7: EWR | G7: KEWR | H7: 46289.012 | I7: 46289.11 | J7: =ROUND((I7-H7)*1440,0) -> 140 | K7: N645JB | L7: A320 | M7: A320 | N7: Complete | O7: a87898
A8: 46289 | B8: B6 2018 | C8: JBU2018 | F8: JFK | G8: KJFK | H8: 46289.013 | I8: 46289.051 | J8: =ROUND((I8-H8)*1440,0) -> 54 | K8: N2038J | L8: A321neo | M8: A21N | N8: Complete | O8: a1a0a1
A9: 46289 | B9: B6 2144 | C9: JBU2144 | D9: DJT | E9: KPBI | F9: EWR | G9: KEWR | H9: 46289.014 | I9: 46289.108 | J9: =ROUND((I9-H9)*1440,0) -> 135 | K9: N535JB | L9: A320 | M9: A320 | N9: Complete | O9: a6c3ca
A10: 46289 | B10: B6 2994 | C10: JBU2994 | D10: FLL | E10: KFLL | F10: BWI | G10: KBWI | H10: 46289.014 | I10: 46289.1 | J10: =ROUND((I10-H10)*1440,0) -> 123 | K10: N3145J | L10: A220-300 | M10: BCS3 | N10: Complete | O10: a358bd
A11: 46289 | B11: B6 1694 | C11: JBU1694 | D11: MCO | E11: KMCO | F11: HPN | G11: KHPN | H11: 46289.014 | I11: 46289.098 | J11: =ROUND((I11-H11)*1440,0) -> 121 | K11: N627JB | L11: A320 | M11: A320 | N11: Landing inferred | O11: a83108
A12: 46289 | B12: B6 560 | C12: JBU560 | D12: PHL | E12: KPHL | F12: BOS | G12: KBOS | H12: 46289.018 | I12: 46289.056 | J12: =ROUND((I12-H12)*1440,0) -> 56 | K12: N3194J | L12: A220-300 | M12: BCS3 | N12: Complete | O12: a36b2d
A13: 46289 | B13: B6 1486 | C13: JBU1486 | D13: RDU | E13: KRDU | F13: JFK | G13: KJFK | H13: 46289.022 | I13: 46289.07 | J13: =ROUND((I13-H13)*1440,0) -> 69 | K13: N3267J | L13: A220-300 | M13: BCS3 | N13: Complete | O13: a387f0
A14: 46289 | B14: B6 810 | C14: JBU810 | D14: JAX | E14: KJAX | F14: BOS | G14: KBOS | H14: 46289.023 | I14: 46289.109 | J14: =ROUND((I14-H14)*1440,0) -> 123 | K14: N623JB | L14: A320 | M14: A320 | N14: Complete | O14: a8222c
A15: 46289 | B15: B6 2581 | C15: JBU2581 | D15: FLL | E15: KFLL | F15: BNA | G15: KBNA | H15: 46289.023 | I15: 46289.104 | J15: =ROUND((I15-H15)*1440,0) -> 116 | K15: N651JB | L15: A320 | M15: A320 | N15: Complete | O15: a8913b
A16: 46289 | B16: B6 2626 | C16: JBU2626 | D16: FLL | E16: KFLL | F16: RDU | G16: KRDU | H16: 46289.025 | I16: 46289.091 | J16: =ROUND((I16-H16)*1440,0) -> 96 | K16: N766JB | L16: A320 | M16: A320 | N16: Complete | O16: aa589c
A17: 46289 | B17: B6 8457 | C17: JBU8457 | D17: ISP | E17: KISP | F17: JFK | G17: KJFK | H17: 46289.025 | I17: 46289.042 | J17: =ROUND((I17-H17)*1440,0) -> 25 | K17: N585JB | L17: A320 | M17: A320 | N17: Complete | O17: a78945
A18: 46289 | B18: B6 277 | C18: JBU277 | D18: FLL | E18: KFLL | F18: SFO | G18: KSFO | H18: 46289.026 | I18: 46289.258 | J18: =ROUND((I18-H18)*1440,0) -> 334 | K18: N968JT | L18: A321 | M18: A321 | N18: Complete | O18: ad7ab8
A19: 46289 | B19: B6 2279 | C19: JBU2279 | D19: FLL | E19: KFLL | F19: DFW | G19: KDFW | H19: 46289.027 | I19: 46289.138 | J19: =ROUND((I19-H19)*1440,0) -> 161 | K19: N527JL | L19: A320 | M19: A320 | N19: Complete | O19: a6a3c2
A20: 46289 | B20: B6 2134 | C20: JBU2134 | F20: MCO | G20: KMCO | H20: 46289.027 | I20: 46289.058 | J20: =ROUND((I20-H20)*1440,0) -> 45 | K20: N523JB | L20: A320 | M20: A320 | N20: Complete | O20: a694dd
A21: 46289 | B21: B6 2322 | C21: JBU2322 | D21: DJT | E21: KPBI | F21: BOS | G21: KBOS | H21: 46289.028 | I21: 46289.132 | J21: =ROUND((I21-H21)*1440,0) -> 149 | K21: N605JB | L21: A320 | M21: A320 | N21: Complete | O21: a7da9c
A22: 46289 | B22: B6 2271 | C22: JBU2271 | D22: FLL | E22: KFLL | F22: AUS | G22: KAUS | H22: 46289.028 | I22: 46289.136 | J22: =ROUND((I22-H22)*1440,0) -> 155 | K22: N597JB | L22: A320 | M22: A320 | N22: Complete | O22: a7b832
A23: 46289 | B23: B6 1136 | C23: JBU1136 | D23: DTW | E23: KDTW | F23: BOS | G23: KBOS | H23: 46289.029 | I23: 46289.096 | J23: =ROUND((I23-H23)*1440,0) -> 97 | K23: N703JB | L23: A320 | M23: A320 | N23: Complete | O23: a9607d
A24: 46289 | B24: B6 2290 | C24: JBU2290 | D24: FLL | E24: KFLL | F24: DTW | G24: KDTW | H24: 46289.029 | I24: 46289.127 | J24: =ROUND((I24-H24)*1440,0) -> 141 | K24: N568JB | L24: A320 | M24: A320 | N24: Complete | O24: a7456c
A25: 46289 | B25: B6 2754 | C25: JBU2754 | D25: DCA | E25: KDCA | F25: BOS | G25: KBOS | H25: 46289.03 | I25: 46289.074 | J25: =ROUND((I25-H25)*1440,0) -> 63 | K25: N3115J | L25: A220-300 | M25: BCS3 | N25: Complete | O25: a34d98
A26: 46289 | B26: B6 514 | C26: JBU514 | D26: FLL | E26: KFLL | F26: ISP | G26: KISP | H26: 46289.03 | I26: 46289.125 | J26: =ROUND((I26-H26)*1440,0) -> 137 | K26: N554JB | L26: A320 | M26: A320 | N26: Landing inferred | O26: a70f11
A27: 46289 | B27: B6 1948 | C27: JBU1948 | D27: FLL | E27: KFLL | F27: MCO | G27: KMCO | H27: 46289.032 | I27: 46289.054 | J27: =ROUND((I27-H27)*1440,0) -> 33 | K27: N625JB | L27: A320 | M27: A320 | N27: Complete | O27: a8299a
A28: 46289 | B28: B6 1196 | C28: JBU1196 | D28: FLL | E28: KFLL | F28: PVD | G28: KPVD | H28: 46289.033 | I28: 46289.134 | J28: =ROUND((I28-H28)*1440,0) -> 146 | K28: N516JB | L28: A320 | M28: A320 | N28: Complete | O28: a67883
A29: 46289 | B29: B6 528 | C29: JBU528 | F29: JFK | G29: KJFK | H29: 46289.033 | I29: 46289.175 | J29: =ROUND((I29-H29)*1440,0) -> 205 | K29: N2048J | L29: A321neo | M29: A21N | N29: Complete | O29: a1a458
A30: 46289 | B30: B6 719 | C30: JBU719 | D30: JFK | E30: KJFK | F30: ATL | G30: KATL | H30: 46289.034 | I30: 46289.11 | J30: =ROUND((I30-H30)*1440,0) -> 109 | K30: N3244J | L30: A220-300 | M30: BCS3 | N30: Complete | O30: a38019
A31: 46289 | B31: B6 251 | C31: JBU251 | D31: BOS | E31: KBOS | F31: MCO | G31: KMCO | H31: 46289.035 | I31: 46289.15 | J31: =ROUND((I31-H31)*1440,0) -> 165 | K31: N957JB | L31: A321 | M31: A321 | N31: Complete | O31: ad4f72
A32: 46289 | B32: B6 1905 | C32: JBU1905 | D32: FLL | E32: KFLL | F32: TPA | G32: KTPA | H32: 46289.036 | I32: 46289.062 | J32: =ROUND((I32-H32)*1440,0) -> 38 | K32: N821JB | L32: A320 | M32: A320 | N32: Complete | O32: ab355c
A33: 46289 | B33: B6 1146 | C33: JBU1146 | D33: FLL | E33: KFLL | F33: RIC | G33: KRIC | H33: 46289.037 | I33: 46289.111 | J33: =ROUND((I33-H33)*1440,0) -> 107 | K33: N663JB | L33: A320 | M33: A320 | N33: Landing inferred | O33: a8c028
A34: 46289 | B34: B6 31 | C34: JBU31 | D34: BOS | E34: KBOS | F34: AMS | G34: EHAM | H34: 46289.038 | I34: 46289.298 | J34: =ROUND((I34-H34)*1440,0) -> 375 | K34: N4064J | L34: A321neo | M34: A21N | N34: Complete | O34: a4c5d8
A35: 46289 | B35: B6 572 | C35: JBU572 | D35: FLL | E35: KFLL | F35: LGA | G35: KLGA | H35: 46289.038 | I35: 46289.137 | J35: =ROUND((I35-H35)*1440,0) -> 143 | K35: N584JB | L35: A320 | M35: A320 | N35: Complete | O35: a7858e
A36: 46289 | B36: B6 1952 | C36: JBU1952 | D36: MCO | E36: KMCO | F36: BOS | G36: KBOS | H36: 46289.039 | I36: 46289.136 | J36: =ROUND((I36-H36)*1440,0) -> 140 | K36: N3293J | L36: A220-300 | M36: BCS3 | N36: Complete | O36: a39289
A37: 46289 | B37: B6 1590 | C37: JBU1590 | D37: FLL | E37: KFLL | F37: CLE | G37: KCLE | H37: 46289.039 | I37: 46289.134 | J37: =ROUND((I37-H37)*1440,0) -> 137 | K37: N3280J | L37: A220-300 | M37: BCS3 | N37: Complete | O37: a38e69
A38: 46289 | B38: B6 2768 | C38: JBU2768 | D38: JFK | E38: KJFK | F38: CLE | G38: KCLE | H38: 46289.04 | I38: 46289.09 | J38: =ROUND((I38-H38)*1440,0) -> 73 | K38: N3269J | L38: A220-300 | M38: BCS3 | N38: Complete | O38: a38836
A39: 46289 | B39: B6 2186 | C39: JBU2186 | D39: PIT | E39: KPIT | F39: BOS | G39: KBOS | H39: 46289.04 | I39: 46289.506 | J39: =ROUND((I39-H39)*1440,0) -> 671 | K39: N3085J | L39: A220-300 | M39: BCS3 | N39: Complete | O39: a3401a
A40: 46289 | B40: B6 845 | C40: JBU845 | D40: BOS | E40: KBOS | F40: SYR | G40: KSYR | H40: 46289.04 | I40: 46289.075 | J40: =ROUND((I40-H40)*1440,0) -> 50 | K40: N3121J | L40: A220-300 | M40: BCS3 | N40: Complete | O40: a350c3
...

Sheet Summary
A1: JetBlue (B6) flights 2026-09-24 to 2026-09-26 (UTC departure date)
A3: Aircraft Type | B3: 2026-09-24 | C3: 2026-09-25 | D3: 2026-09-26 | E3: Total | F3: Unique Tails
A4: A220-300 | B4: =COUNTIFS(Flights!$A$2:$A$2331,DATEVALUE(B$3),Flights!$L$2:$L$2331,$A4) -> 190 | C4: =COUNTIFS(Flights!$A$2:$A$2331,DATEVALUE(C$3),Flights!$L$2:$L$2331,$A4) -> 204 | D4: =COUNTIFS(Flights!$A$2:$A$2331,DATEVALUE(D$3),Flights!$L$2:$L$2331,$A4) -> 179 | E4: =SUM(B4:D4) -> 573 | F4: 59
A5: A320 | B5: =COUNTIFS(Flights!$A$2:$A$2331,DATEVALUE(B$3),Flights!$L$2:$L$2331,$A5) -> 308 | C5: =COUNTIFS(Flights!$A$2:$A$2331,DATEVALUE(C$3),Flights!$L$2:$L$2331,$A5) -> 318 | D5: =COUNTIFS(Flights!$A$2:$A$2331,DATEVALUE(D$3),Flights!$L$2:$L$2331,$A5) -> 303 | E5: =SUM(B5:D5) -> 929 | F5: 111
A6: A321 | B6: =COUNTIFS(Flights!$A$2:$A$2331,DATEVALUE(B$3),Flights!$L$2:$L$2331,$A6) -> 148 | C6: =COUNTIFS(Flights!$A$2:$A$2331,DATEVALUE(C$3),Flights!$L$2:$L$2331,$A6) -> 147 | D6: =COUNTIFS(Flights!$A$2:$A$2331,DATEVALUE(D$3),Flights!$L$2:$L$2331,$A6) -> 134 | E6: =SUM(B6:D6) -> 429 | F6: 61
A7: A321neo | B7: =COUNTIFS(Flights!$A$2:$A$2331,DATEVALUE(B$3),Flights!$L$2:$L$2331,$A7) -> 66 | C7: =COUNTIFS(Flights!$A$2:$A$2331,DATEVALUE(C$3),Flights!$L$2:$L$2331,$A7) -> 63 | D7: =COUNTIFS(Flights!$A$2:$A$2331,DATEVALUE(D$3),Flights!$L$2:$L$2331,$A7) -> 63 | E7: =SUM(B7:D7) -> 192 | F7: 33
A8: Unknown | B8: =COUNTIFS(Flights!$A$2:$A$2331,DATEVALUE(B$3),Flights!$L$2:$L$2331,$A8) -> 46 | C8: =COUNTIFS(Flights!$A$2:$A$2331,DATEVALUE(C$3),Flights!$L$2:$L$2331,$A8) -> 16 | D8: =COUNTIFS(Flights!$A$2:$A$2331,DATEVALUE(D$3),Flights!$L$2:$L$2331,$A8) -> 145 | E8: =SUM(B8:D8) -> 207 | F8: 4
A9: Total | B9: =SUM(B4:B8) -> 758 | C9: =SUM(C4:C8) -> 748 | D9: =SUM(D4:D8) -> 824 | E9: =SUM(E4:E8) -> 2330
A11: Unique Tails = distinct registrations seen (computed by script).

Sheet Fleet
A1: Tail Number | B1: Aircraft Type | C1: ICAO Type | D1: Flights
A2: N3023J | B2: A220-300 | C2: BCS3 | D2: =COUNTIF(Flights!$K$2:$K$2331,A2) -> 9
A3: N3044J | B3: A220-300 | C3: BCS3 | D3: =COUNTIF(Flights!$K$2:$K$2331,A3) -> 6
A4: N3058J | B4: A220-300 | C4: BCS3 | D4: =COUNTIF(Flights!$K$2:$K$2331,A4) -> 10
A5: N3062J | B5: A220-300 | C5: BCS3 | D5: =COUNTIF(Flights!$K$2:$K$2331,A5) -> 4
A6: N3065J | B6: A220-300 | C6: BCS3 | D6: =COUNTIF(Flights!$K$2:$K$2331,A6) -> 12
A7: N3077J | B7: A220-300 | C7: BCS3 | D7: =COUNTIF(Flights!$K$2:$K$2331,A7) -> 15
A8: N3085J | B8: A220-300 | C8: BCS3 | D8: =COUNTIF(Flights!$K$2:$K$2331,A8) -> 10
A9: N3102J | B9: A220-300 | C9: BCS3 | D9: =COUNTIF(Flights!$K$2:$K$2331,A9) -> 9
A10: N3104J | B10: A220-300 | C10: BCS3 | D10: =COUNTIF(Flights!$K$2:$K$2331,A10) -> 7
A11: N3112J | B11: A220-300 | C11: BCS3 | D11: =COUNTIF(Flights!$K$2:$K$2331,A11) -> 10
A12: N3113J | B12: A220-300 | C12: BCS3 | D12: =COUNTIF(Flights!$K$2:$K$2331,A12) -> 13
A13: N3115J | B13: A220-300 | C13: BCS3 | D13: =COUNTIF(Flights!$K$2:$K$2331,A13) -> 11
... A265: N4083J | B265: A321neo | C265: A21N | D265: =COUNTIF(Flights!$K$2:$K$2331,A265) -> 7
A266: N3289J | B266: Unknown | D266: =COUNTIF(Flights!$K$2:$K$2331,A266) -> 12
A267: N3298J | B267: Unknown | D267: =COUNTIF(Flights!$K$2:$K$2331,A267) -> 8
A268: N3310J | B268: Unknown | D268: =COUNTIF(Flights!$K$2:$K$2331,A268) -> 174
A269: N3322J | B269: Unknown | D269: =COUNTIF(Flights!$K$2:$K$2331,A269) -> 13

Sheet Notes
A1: Sources
A2: ADS-B traces: adsb.lol globe_history daily archives (ODbL), github.com/adsblol
A3: Tail number and ICAO type: from adsb.lol aircraft database embedded in traces.
A4: Airports: OurAirports - nearest large/medium airport within 15 km of takeoff/landing.
A6: Caveats
A7: All times UTC. Departure = wheels-off, Arrival = touchdown (not gate times).
A8: Status: Complete = takeoff and landing seen; Landing inferred = signal lost low near airport;
A9: Signal lost = coverage gap at altitude (destination may be blank);
A10: Airborne at end of data = still flying when the last day's archive ended.
A11: Flights are included when the callsign starts with JBU (or no callsign on a JetBlue-owned aircraft).
A12: Generated 2026-09-27 18:13 local time.
