Workbook

Sheet Legend
A1: FuelSphere - Fuel Data Model Test Scenarios
A2: Test data covering flight operations, flight dispatch fuel plan, fuel order and fuel ticket
A5: SHEET | B5: PURPOSE
A6: Test Scenarios | B6: Master list of test cases with trigger, expected system behaviour and validation focus
A7: FLIGHT_OPERATIONS | B7: Flight leg master. One row per operating leg. Parent of all fuel records
A8: FD_FUEL_PLAN | B8: Flight dispatch fuel plan. One row per plan VERSION. Never updated in place
A9: FUEL_ORDER | B9: Order placed to the into-plane supplier. Derived from a plan version
A10: FUEL_TICKET | B10: Physical fuel event record. Uplift, defuel or jettison
A11: FUEL_INVOICE | B11: Supplier invoice header including the posting lifecycle
A12: FUEL_INVOICE_LINE | B12: One billed uplift. Completes the three way match
A13: FUEL_PARAMETER | B13: Configuration. Tolerances, conversion density, density limits
A14: FUEL_PARAMETER_APPLIED | B14: Immutable record of which config row applied to a transaction
A15: APPLICATION_LOG | B15: Posting attempts, errors and warnings. Source for the error screens
A16: AI_SETTING | B16: AI provider, limits and governance so features bind to the organisation ecosystem
... A53: PAID | B53: Payment settled in the finance system

Sheet Test Scenarios
A1: Test Scenario Catalogue
A2: TC_ID | B2: Scenario | C2: Category | D2: Trigger | E2: Expected System Behaviour | F2: Primary Validation Focus
A3: TC01 | B3: Baseline single uplift | C3: Happy path | D3: Flight planned, fuelled and departed with no change | E3: One plan version, one order, one ticket. Ticket matched to order and plan | F3: 1:1:1 linkage; variance within meter tolerance
A4: TC02 | B4: Plan update before fuelling | C4: Re-plan | D4: Payload increase raises ZFW before the bowser connects | E4: New plan version created. Existing order amended to v2. Single ticket against amended order | F4: Order versioning; plan v1 marked SUPERSEDED; no orphan ticket
A5: TC03 | B5: Plan update after fuelling | C5: Re-plan | D5: ATC reroute after uplift completed | E5: New plan version. Required uplift computed as delta against actual FOB, not arrival FOB. Separate TOP_UP order and second ticket | F5: required_uplift = block_fuel - actual FOB including prior tickets
A6: TC04 | B6: Tail swap after fuelling | C6: Disruption | D6: Original tail goes tech after uplift; flight moved to another registration | E6: New plan version with new registration. First ticket stays valid but unlinked from the leg. Second order and ticket against the new tail | F6: Ticket keyed to registration not flight; orphan ticket retained not deleted
A7: TC05 | B7: Multiple tickets per order | C7: Multi-ticket | D7: Widebody uplift exceeds single bowser capacity | E7: One order, two tickets with uplift_sequence 1 and 2. Order delivered quantity is the SUM of tickets | F7: Order rollup summed from tickets, never stored as a scalar
A8: TC06 | B8: Interrupted fuelling | C8: Multi-ticket | D8: Fuelling stopped mid-uplift when alternate changed, resumed under a new order | E8: First order shows PART_FULFILLED with under-delivery. New order covers the balance | F8: Under-delivery flagged with a reason code, not treated as supplier shortfall
A9: TC07 | B9: Cancelled flight after fuelling | C9: Disruption | D9: Flight cancelled after fuel already delivered | E9: Leg status CANCELLED. Ticket remains valid and billable. Cost allocated to aircraft not flight leg | F9: cost_allocation_basis populated; ticket not orphaned or voided
A10: TC08 | B10: Return to ramp with defuel | C10: Return | D10: Aircraft returns to stand before takeoff; replacement routing is shorter | E10: New plan version. DEFUEL event recorded as a negative quantity ticket | F10: Negative quantity accepted; FOB delta negative and consistent
A11: TC09 | B11: Air return with jettison | C11: Return | D11: Aircraft returns to departure station airborne and jettisons fuel to reach MLW | E11: JETTISON event recorded with quantity from FQIS and no meter reading or density | F11: Non-metered event supported; burn variance not inflated by unrecorded jettison
A12: TC10 | B12: Ticket with no order | C12: Exception | D12: Post-freeze top-up requested verbally at the aircraft | E12: Ticket created with null fuel_order_id and match_status UNMATCHED, pending reconciliation | F12: Nullable FK; ticket not rejected at ingestion
A13: TC11 | B13: Captain discretionary fuel | C13: Re-plan | D13: Commander requests extra fuel for expected holding at destination | E13: New plan version with extra_fuel populated and a discretionary reason code | F13: extra_fuel separated from additional_fuel; reason code captured
... A159: TC67 | B159: Delta sequence gap detected | C159: Interface | D159: Intraday delta stream skips a sequence number | E159: Gap raised on the run. Snapshot run resets the expected sequence position | F159: Gap detection scoped to the delta stream only

Sheet FLIGHT_OPERATIONS
A1: FLIGHT_OPERATIONS - PK flight_leg_id | UK airline_code + flight_number + sched_dep_date_utc + leg_sequence | OOOI, stand, weight and payload fields feed burn derivation and variance analysis
A2: TC_ID | B2: flight_leg_id | C2: airline_code | D2: flight_number | E2: sched_dep_date_utc | F2: leg_sequence | G2: operating_carrier | H2: marketing_carrier | I2: codeshare_numbers | J2: service_type | K2: flight_nature | L2: departure_station | M2: arrival_station | N2: sched_dep_station | O2: sched_arr_station | P2: route_sequence | Q2: is_multi_leg | R2: std_utc | S2: sta_utc | T2: etd_utc | U2: eta_utc | V2: out_utc | W2: off_utc | X2: on_utc | Y2: in_utc | Z2: block_minutes | AA2: flight_minutes | AB2: taxi_out_minutes | AC2: taxi_in_minutes | AD2: aircraft_type_id | AE2: aircraft_config_id | AF2: planned_registration | AG2: actual_registration | AH2: tail_change_flag | AI2: dep_stand | AJ2: dep_stand_type | AK2: arr_stand | AL2: arr_stand_type | AM2: dep_runway | AN2: arr_runway | AO2: flight_status | AP2: ops_phase | AQ2: return_type | AR2: status_reason | AS2: status_updated_utc | AT2: sync_status | AU2: pending_field_summary | AV2: delay_code | AW2: delay_minutes | AX2: diversion_station | AY2: cancellation_reason | AZ2: pax_booked | BA2: pax_actual | BB2: cargo_kg | BC2: mail_kg | BD2: bag_kg | BE2: actual_zfw_kg | BF2: actual_tow_kg | BG2: actual_lw_kg | BH2: loadsheet_ref | BI2: cruise_level_planned | BJ2: cruise_level_flown | BK2: alternate_planned | BL2: alternate_used | BM2: single_engine_taxi_flag | BN2: deicing_flag | BO2: apu_reported_flag | BP2: fuel_processing_mode | BQ2: resolved_arrangement_id | BR2: provisional_tail_flag | BS2: fuel_reconciled_flag | BT2: burn_capture_status
A3: TC01 | B3: LEG-26081401 | C3: PR | D3: 0126 | E3: 2026-08-14 | F3: 1 | G3: PR | H3: PR | J3: J | K3: REVENUE | L3: MNL | M3: SIN | N3: MNL | O3: SIN | P3: 1 | Q3: N | R3: 46248.25 | S3: 46248.41 | V3: 46248.253 | W3: 46248.263 | X3: 46248.401 | Y3: 46248.411 | Z3: =IF(OR(V3="",Y3=""),"",ROUND((Y3-V3)*1440,0)) -> 228 | AA3: =IF(OR(W3="",X3=""),"",ROUND((X3-W3)*1440,0)) -> 199 | AB3: =IF(OR(V3="",W3=""),"",ROUND((W3-V3)*1440,0)) -> 15 | AC3: =IF(OR(X3="",Y3=""),"",ROUND((Y3-X3)*1440,0)) -> 14 | AD3: A321 | AF3: RP-C4108 | AG3: RP-C4108 | AH3: N | AI3: S12 | AJ3: CONTACT | AK3: B04 | AL3: CONTACT | AO3: ARRIVED | AP3: ON_BLOCKS | AT3: CURRENT | AW3: =IF(OR(V3="",R3=""),"",ROUND((V3-R3)*1440,0)) -> 4 | AZ3: 168 | BA3: 161 | BB3: 4200 | BC3: 0 | BD3: 0 | BE3: 68400 | BF3: 79651 | BG3: 71231 | BH3: LS-081401 | BI3: 350 | BJ3: 350 | BK3: WSSS | BL3: WSSS | BM3: Y | BN3: N | BO3: Y | BP3: FULL | BQ3: CAR-01 | BR3: N | BS3: Y | BT3: COMPLETE
A4: TC02 | B4: LEG-26081402 | C4: PR | D4: 0128 | E4: 2026-08-14 | F4: 1 | G4: PR | H4: PR | J4: J | K4: REVENUE | L4: MNL | M4: SIN | N4: MNL | O4: SIN | P4: 1 | Q4: N | R4: 46248.458 | S4: 46248.618 | V4: 46248.467 | W4: 46248.478 | X4: 46248.612 | Y4: 46248.622 | Z4: =IF(OR(V4="",Y4=""),"",ROUND((Y4-V4)*1440,0)) -> 223 | AA4: =IF(OR(W4="",X4=""),"",ROUND((X4-W4)*1440,0)) -> 192 | AB4: =IF(OR(V4="",W4=""),"",ROUND((W4-V4)*1440,0)) -> 17 | AC4: =IF(OR(X4="",Y4=""),"",ROUND((Y4-X4)*1440,0)) -> 14 | AD4: A321 | AF4: RP-C4110 | AG4: RP-C4110 | AH4: N | AI4: S14 | AJ4: CONTACT | AK4: B07 | AL4: CONTACT | AO4: ARRIVED | AP4: ON_BLOCKS | AT4: CURRENT | AW4: =IF(OR(V4="",R4=""),"",ROUND((V4-R4)*1440,0)) -> 12 | AZ4: 180 | BA4: 177 | BB4: 5100 | BC4: 0 | BD4: 0 | BE4: 71200 | BF4: 82735 | BG4: 74045 | BH4: LS-081402 | BI4: 350 | BJ4: 370 | BK4: WSSS | BL4: WSSS | BM4: Y | BN4: N | BO4: Y | BP4: FULL | BQ4: CAR-01 | BR4: N | BS4: Y | BT4: PARTIAL
A5: TC03 | B5: LEG-26081403 | C5: PR | D5: 0130 | E5: 2026-08-14 | F5: 1 | G5: PR | H5: PR | J5: J | K5: REVENUE | L5: MNL | M5: SIN | N5: MNL | O5: SIN | P5: 1 | Q5: N | R5: 46248.625 | S5: 46248.785 | V5: 46248.653 | W5: 46248.665 | X5: 46248.8 | Y5: 46248.81 | Z5: =IF(OR(V5="",Y5=""),"",ROUND((Y5-V5)*1440,0)) -> 225 | AA5: =IF(OR(W5="",X5=""),"",ROUND((X5-W5)*1440,0)) -> 194 | AB5: =IF(OR(V5="",W5=""),"",ROUND((W5-V5)*1440,0)) -> 17 | AC5: =IF(OR(X5="",Y5=""),"",ROUND((Y5-X5)*1440,0)) -> 14 | AD5: A321 | AF5: RP-C4112 | AG5: RP-C4112 | AH5: N | AI5: S09 | AJ5: CONTACT | AK5: B02 | AL5: CONTACT | AO5: ARRIVED | AP5: ON_BLOCKS | AT5: CURRENT | AV5: 81 | AW5: =IF(OR(V5="",R5=""),"",ROUND((V5-R5)*1440,0)) -> 41 | AZ5: 172 | BA5: 170 | BB5: 4600 | BC5: 0 | BD5: 0 | BE5: 69100 | BF5: 81387 | BG5: 71987 | BH5: LS-081403 | BI5: 350 | BJ5: 330 | BK5: WSSS | BL5: WSSS | BM5: N | BN5: N | BO5: Y | BP5: FULL | BQ5: CAR-01 | BR5: N | BS5: Y | BT5: PARTIAL
A6: TC04 | B6: LEG-26081404 | C6: PR | D6: 0132 | E6: 2026-08-14 | F6: 1 | G6: PR | H6: PR | J6: J | K6: REVENUE | L6: MNL | M6: SIN | N6: MNL | O6: SIN | P6: 1 | Q6: N | R6: 46248.75 | S6: 46248.91 | V6: 46248.788 | W6: 46248.799 | X6: 46248.937 | Y6: 46248.947 | Z6: =IF(OR(V6="",Y6=""),"",ROUND((Y6-V6)*1440,0)) -> 229 | AA6: =IF(OR(W6="",X6=""),"",ROUND((X6-W6)*1440,0)) -> 198 | AB6: =IF(OR(V6="",W6=""),"",ROUND((W6-V6)*1440,0)) -> 16 | AC6: =IF(OR(X6="",Y6=""),"",ROUND((Y6-X6)*1440,0)) -> 15 | AD6: A321 | AF6: RP-C4108 | AG6: RP-C4109 | AH6: Y | AI6: S11 | AJ6: CONTACT | AK6: B09 | AL6: CONTACT | AO6: ARRIVED | AP6: ON_BLOCKS | AR6: TAIL_SWAP | AT6: CURRENT | AV6: 41 | AW6: =IF(OR(V6="",R6=""),"",ROUND((V6-R6)*1440,0)) -> 55 | AZ6: 166 | BA6: 158 | BB6: 3900 | BC6: 0 | BD6: 0 | BE6: 67800 | BF6: 79446 | BG6: 70936 | BH6: LS-081404 | BI6: 350 | BJ6: 350 | BK6: WSSS | BL6: WSSS | BM6: Y | BN6: N | BO6: Y | BP6: FULL | BQ6: CAR-01 | BR6: N | BS6: Y | BT6: COMPLETE
A7: TC05 | B7: LEG-26081405 | C7: PR | D7: 0102 | E7: 2026-08-14 | F7: 1 | G7: PR | H7: PR | I7: KE7702 | J7: J | K7: REVENUE | L7: MNL | M7: LAX | N7: MNL | O7: LAX | P7: 1 | Q7: N | R7: 46248.556 | S7: 46249.045 | V7: 46248.56 | W7: 46248.572 | X7: 46249.035 | Y7: 46249.045 | Z7: =IF(OR(V7="",Y7=""),"",ROUND((Y7-V7)*1440,0)) -> 699 | AA7: =IF(OR(W7="",X7=""),"",ROUND((X7-W7)*1440,0)) -> 667 | AB7: =IF(OR(V7="",W7=""),"",ROUND((W7-V7)*1440,0)) -> 18 | AC7: =IF(OR(X7="",Y7=""),"",ROUND((Y7-X7)*1440,0)) -> 14 | AD7: A350-900 | AF7: RP-C3505 | AG7: RP-C3505 | AH7: N | AI7: S22 | AJ7: CONTACT | AK7: T148 | AL7: CONTACT | AO7: ARRIVED | AP7: ON_BLOCKS | AT7: CURRENT | AW7: =IF(OR(V7="",R7=""),"",ROUND((V7-R7)*1440,0)) -> 6 | AZ7: 289 | BA7: 281 | BB7: 18400 | BC7: 0 | BD7: 0 | BE7: 178300 | BF7: 283692 | BG7: 187292 | BH7: LS-081405 | BI7: 340 | BJ7: 360 | BK7: KSFO | BL7: KSFO | BM7: Y | BN7: N | BO7: Y | BP7: FULL | BQ7: CAR-01 | BR7: N | BS7: Y | BT7: COMPLETE
A8: TC06 | B8: LEG-26081406 | C8: PR | D8: 0104 | E8: 2026-08-15 | F8: 1 | G8: PR | H8: PR | J8: J | K8: REVENUE | L8: MNL | M8: LAX | N8: MNL | O8: LAX | P8: 1 | Q8: N | R8: 46249.556 | S8: 46250.045 | V8: 46249.582 | W8: 46249.594 | X8: 46250.057 | Y8: 46250.067 | Z8: =IF(OR(V8="",Y8=""),"",ROUND((Y8-V8)*1440,0)) -> 698 | AA8: =IF(OR(W8="",X8=""),"",ROUND((X8-W8)*1440,0)) -> 666 | AB8: =IF(OR(V8="",W8=""),"",ROUND((W8-V8)*1440,0)) -> 18 | AC8: =IF(OR(X8="",Y8=""),"",ROUND((Y8-X8)*1440,0)) -> 14 | AD8: A350-900 | AF8: RP-C3507 | AG8: RP-C3507 | AH8: N | AI8: S22 | AJ8: CONTACT | AK8: T148 | AL8: CONTACT | AO8: ARRIVED | AP8: ON_BLOCKS | AT8: CURRENT | AV8: 89 | AW8: =IF(OR(V8="",R8=""),"",ROUND((V8-R8)*1440,0)) -> 38 | AZ8: 291 | BA8: 288 | BB8: 19100 | BC8: 0 | BD8: 0 | BE8: 179000 | BF8: 287142 | BG8: 187942 | BH8: LS-081406 | BI8: 340 | BJ8: 340 | BK8: KSFO | BL8: KSFO | BM8: Y | BN8: N | BO8: Y | BP8: FULL | BQ8: CAR-01 | BR8: N | BS8: Y | BT8: COMPLETE
A9: TC07 | B9: LEG-26081407 | C9: PR | D9: 0134 | E9: 2026-08-15 | F9: 1 | G9: PR | H9: PR | J9: J | K9: REVENUE | L9: MNL | M9: SIN | N9: MNL | O9: SIN | P9: 1 | Q9: N | R9: 46249.25 | S9: 46249.41 | Z9: =IF(OR(V9="",Y9=""),"",ROUND((Y9-V9)*1440,0)) | AA9: =IF(OR(W9="",X9=""),"",ROUND((X9-W9)*1440,0)) | AB9: =IF(OR(V9="",W9=""),"",ROUND((W9-V9)*1440,0)) | AC9: =IF(OR(X9="",Y9=""),"",ROUND((Y9-X9)*1440,0)) | AD9: A321 | AF9: RP-C4114 | AG9: RP-C4114 | AH9: N | AI9: S07 | AJ9: CONTACT | AO9: CANCELLED | AP9: NOT_STARTED | AR9: TECHNICAL | AT9: CURRENT | AV9: 41 | AW9: =IF(OR(V9="",R9=""),"",ROUND((V9-R9)*1440,0)) | AY9: TECHNICAL | AZ9: 165 | BA9: 0 | BB9: 0 | BC9: 0 | BD9: 0 | BH9: LS-081407 | BI9: 350 | BK9: WSSS | BM9: N | BN9: N | BO9: Y | BP9: FULL | BQ9: CAR-01 | BR9: N | BS9: N | BT9: NOT_CAPTURED
A10: TC08 | B10: LEG-26081408 | C10: PR | D10: 0136 | E10: 2026-08-15 | F10: 1 | G10: PR | H10: PR | J10: J | K10: REVENUE | L10: MNL | M10: SIN | N10: MNL | O10: SIN | P10: 1 | Q10: N | R10: 46249.458 | S10: 46249.618 | V10: 46249.464 | Y10: 46249.494 | Z10: =IF(OR(V10="",Y10=""),"",ROUND((Y10-V10)*1440,0)) -> 44 | AA10: =IF(OR(W10="",X10=""),"",ROUND((X10-W10)*1440,0)) | AB10: =IF(OR(V10="",W10=""),"",ROUND((W10-V10)*1440,0)) | AC10: =IF(OR(X10="",Y10=""),"",ROUND((Y10-X10)*1440,0)) | AD10: A321 | AF10: RP-C4116 | AG10: RP-C4116 | AH10: N | AI10: S16 | AJ10: CONTACT | AK10: S16 | AL10: CONTACT | AO10: RETURN_TO_RAMP | AP10: ON_BLOCKS | AQ10: RAMP | AR10: TECHNICAL | AT10: CURRENT | AV10: 41 | AW10: =IF(OR(V10="",R10=""),"",ROUND((V10-R10)*1440,0)) -> 8 | AZ10: 174 | BA10: 171 | BB10: 4400 | BC10: 0 | BD10: 0 | BE10: 70200 | BF10: 81451 | BH10: LS-081408 | BI10: 350 | BK10: WSSS | BM10: N | BN10: N | BO10: Y | BP10: FULL | BQ10: CAR-01 | BR10: N | BS10: Y | BT10: PARTIAL
A11: TC09 | B11: LEG-26081409 | C11: PR | D11: 0106 | E11: 2026-08-15 | F11: 1 | G11: PR | H11: PR | J11: J | K11: REVENUE | L11: MNL | M11: LAX | N11: MNL | O11: LAX | P11: 1 | Q11: N | R11: 46249.556 | S11: 46250.045 | V11: 46249.558 | W11: 46249.57 | X11: 46249.606 | Y11: 46249.616 | Z11: =IF(OR(V11="",Y11=""),"",ROUND((Y11-V11)*1440,0)) -> 83 | AA11: =IF(OR(W11="",X11=""),"",ROUND((X11-W11)*1440,0)) -> 51 | AB11: =IF(OR(V11="",W11=""),"",ROUND((W11-V11)*1440,0)) -> 17 | AC11: =IF(OR(X11="",Y11=""),"",ROUND((Y11-X11)*1440,0)) -> 15 | AD11: A350-900 | AF11: RP-C3509 | AG11: RP-C3509 | AH11: N | AI11: S24 | AJ11: CONTACT | AK11: S24 | AL11: CONTACT | AO11: AIR_RETURN | AP11: ON_BLOCKS | AQ11: AIR | AR11: MEDICAL | AT11: CURRENT | AV11: 63 | AW11: =IF(OR(V11="",R11=""),"",ROUND((V11-R11)*1440,0)) -> 4 | AZ11: 286 | BA11: 279 | BB11: 17800 | BC11: 0 | BD11: 0 | BE11: 177600 | BF11: 283592 | BG11: 207000 | BH11: LS-081409 | BI11: 340 | BJ11: 260 | BK11: KSFO | BL11: RPLL | BM11: Y | BN11: N | BO11: Y | BP11: FULL | BQ11: CAR-01 | BR11: N | BS11: Y | BT11: COMPLETE
A12: TC10 | B12: LEG-26081410 | C12: PR | D12: 0138 | E12: 2026-08-16 | F12: 1 | G12: PR | H12: PR | J12: J | K12: REVENUE | L12: MNL | M12: SIN | N12: MNL | O12: SIN | P12: 1 | Q12: N | R12: 46250.25 | S12: 46250.41 | V12: 46250.262 | W12: 46250.274 | X12: 46250.411 | Y12: 46250.422 | Z12: =IF(OR(V12="",Y12=""),"",ROUND((Y12-V12)*1440,0)) -> 229 | AA12: =IF(OR(W12="",X12=""),"",ROUND((X12-W12)*1440,0)) -> 197 | AB12: =IF(OR(V12="",W12=""),"",ROUND((W12-V12)*1440,0)) -> 17 | AC12: =IF(OR(X12="",Y12=""),"",ROUND((Y12-X12)*1440,0)) -> 15 | AD12: A321 | AF12: RP-C4118 | AG12: RP-C4118 | AH12: N | AI12: S12 | AJ12: CONTACT | AK12: B04 | AL12: CONTACT | AO12: ARRIVED | AP12: ON_BLOCKS | AT12: CURRENT | AW12: =IF(OR(V12="",R12=""),"",ROUND((V12-R12)*1440,0)) -> 18 | AZ12: 169 | BA12: 164 | BB12: 4300 | BC12: 0 | BD12: 0 | BE12: 68600 | BF12: 80486 | BG12: 71286 | BH12: LS-081410 | BI12: 350 | BJ12: 350 | BK12: WSSS | BL12: WSSS | BM12: Y | BN12: N | BO12: Y | BP12: FULL | BQ12: CAR-01 | BR12: N | BS12: N | BT12: PARTIAL
A13: TC11 | B13: LEG-26081411 | C13: PR | D13: 0140 | E13: 2026-08-16 | F13: 1 | G13: PR | H13: PR | J13: J | K13: REVENUE | L13: MNL | M13: SIN | N13: MNL | O13: SIN | P13: 1 | Q13: N | R13: 46250.458 | S13: 46250.618 | V13: 46250.46 | W13: 46250.472 | X13: 46250.61 | Y13: 46250.619 | Z13: =IF(OR(V13="",Y13=""),"",ROUND((Y13-V13)*1440,0)) -> 229 | AA13: =IF(OR(W13="",X13=""),"",ROUND((X13-W13)*1440,0)) -> 198 | AB13: =IF(OR(V13="",W13=""),"",ROUND((W13-V13)*1440,0)) -> 17 | AC13: =IF(OR(X13="",Y13=""),"",ROUND((Y13-X13)*1440,0)) -> 14 | AD13: A321 | AF13: RP-C4120 | AG13: RP-C4120 | AH13: N | AI13: S14 | AJ13: CONTACT | AK13: B07 | AL13: CONTACT | AO13: ARRIVED | AP13: ON_BLOCKS | AT13: CURRENT | AW13: =IF(OR(V13="",R13=""),"",ROUND((V13-R13)*1440,0)) -> 3 | AZ13: 171 | BA13: 168 | BB13: 4500 | BC13: 0 | BD13: 0 | BE13: 68900 | BF13: 81051 | BG13: 71551 | BH13: LS-081411 | BI13: 350 | BJ13: 350 | BK13: WSSS | BL13: WSSS | BM13: Y | BN13: N | BO13: Y | BP13: FULL | BQ13: CAR-01 | BR13: N | BS13: Y | BT13: ESTIMATED
A14: TC12 | B14: LEG-26081412 | C14: PR | D14: 0142 | E14: 2026-08-16 | F14: 1 | G14: PR | H14: PR | J14: J | K14: REVENUE | L14: MNL | M14: SIN | N14: MNL | O14: SIN | P14: 1 | Q14: N | R14: 46250.625 | S14: 46250.785 | V14: 46250.628 | W14: 46250.64 | X14: 46250.778 | Y14: 46250.788 | Z14: =IF(OR(V14="",Y14=""),"",ROUND((Y14-V14)*1440,0)) -> 230 | AA14: =IF(OR(W14="",X14=""),"",ROUND((X14-W14)*1440,0)) -> 199 | AB14: =IF(OR(V14="",W14=""),"",ROUND((W14-V14)*1440,0)) -> 17 | AC14: =IF(OR(X14="",Y14=""),"",ROUND((Y14-X14)*1440,0)) -> 14 | AD14: A321 | AF14: RP-C4122 | AG14: RP-C4122 | AH14: N | AI14: S09 | AJ14: CONTACT | AK14: B02 | AL14: CONTACT | AO14: ARRIVED | AP14: ON_BLOCKS | AT14: CURRENT | AW14: =IF(OR(V14="",R14=""),"",ROUND((V14-R14)*1440,0)) -> 5 | AZ14: 176 | BA14: 173 | BB14: 4800 | BC14: 0 | BD14: 0 | BE14: 69800 | BF14: 81190 | BG14: 71690 | BH14: LS-081412 | BI14: 350 | BJ14: 350 | BK14: WSSS | BL14: WSSS | BM14: Y | BN14: N | BO14: Y | BP14: FULL | BQ14: CAR-01 | BR14: N | BS14: Y | BT14: COMPLETE
A15: TC13 | B15: LEG-26081413 | C15: PR | D15: 0108 | E15: 2026-08-16 | F15: 1 | G15: PR | H15: PR | J15: J | K15: REVENUE | L15: MNL | M15: LAX | N15: MNL | O15: LAX | P15: 1 | Q15: N | R15: 46250.556 | S15: 46251.045 | V15: 46250.562 | W15: 46250.575 | X15: 46250.822 | Y15: 46250.832 | Z15: =IF(OR(V15="",Y15=""),"",ROUND((Y15-V15)*1440,0)) -> 388 | AA15: =IF(OR(W15="",X15=""),"",ROUND((X15-W15)*1440,0)) -> 356 | AB15: =IF(OR(V15="",W15=""),"",ROUND((W15-V15)*1440,0)) -> 18 | AC15: =IF(OR(X15="",Y15=""),"",ROUND((Y15-X15)*1440,0)) -> 14 | AD15: A350-900 | AF15: RP-C3511 | AG15: RP-C3511 | AH15: N | AI15: S22 | AJ15: CONTACT | AK15: R12 | AL15: REMOTE | AO15: DIVERTED | AP15: ON_BLOCKS | AR15: WEATHER | AT15: CURRENT | AV15: 71 | AW15: =IF(OR(V15="",R15=""),"",ROUND((V15-R15)*1440,0)) -> 10 | AX15: CEB | AZ15: 284 | BA15: 277 | BB15: 17200 | BC15: 0 | BD15: 0 | BE15: 176800 | BF15: 282192 | BH15: LS-081413 | BI15: 340 | BJ15: 320 | BK15: KSFO | BL15: RPVM | BM15: Y | BN15: N | BO15: Y | BP15: FULL | BQ15: CAR-01 | BR15: N | BS15: N | BT15: NOT_CAPTURED
A16: TC14 | B16: LEG-26081414 | C16: PR | D16: 0144 | E16: 2026-08-17 | F16: 1 | G16: PR | H16: PR | J16: J | K16: REVENUE | L16: MNL | M16: SIN | N16: MNL | O16: SIN | P16: 1 | Q16: N | R16: 46251.25 | S16: 46251.41 | V16: 46251.251 | W16: 46251.263 | X16: 46251.4 | Y16: 46251.41 | Z16: =IF(OR(V16="",Y16=""),"",ROUND((Y16-V16)*1440,0)) -> 228 | AA16: =IF(OR(W16="",X16=""),"",ROUND((X16-W16)*1440,0)) -> 197 | AB16: =IF(OR(V16="",W16=""),"",ROUND((W16-V16)*1440,0)) -> 17 | AC16: =IF(OR(X16="",Y16=""),"",ROUND((Y16-X16)*1440,0)) -> 14 | AD16: A321 | AF16: RP-C4124 | AG16: RP-C4124 | AH16: N | AI16: S12 | AJ16: CONTACT | AK16: B04 | AL16: CONTACT | AO16: ARRIVED | AP16: ON_BLOCKS | AT16: CURRENT | AW16: =IF(OR(V16="",R16=""),"",ROUND((V16-R16)*1440,0)) -> 2 | AZ16: 170 | BA16: 167 | BB16: 4400 | BC16: 0 | BD16: 0 | BE16: 68700 | BF16: 83151 | BG16: 71451 | BH16: LS-081414 | BI16: 350 | BJ16: 350 | BK16: WSSS | BL16: WSSS | BM16: Y | BN16: N | BO16: Y | BP16: FULL | BQ16: CAR-01 | BR16: N | BS16: Y | BT16: COMPLETE
A17: TC15 | B17: LEG-26081415 | C17: PR | D17: 0150 | E17: 2026-08-17 | F17: 1 | G17: PR | H17: PR | J17: J | K17: REVENUE | L17: MNL | M17: CEB | N17: MNL | O17: CEB | P17: 1 | Q17: N | R17: 46251.292 | S17: 46251.354 | V17: 46251.294 | W17: 46251.305 | X17: 46251.346 | Y17: 46251.354 | Z17: =IF(OR(V17="",Y17=""),"",ROUND((Y17-V17)*1440,0)) -> 86 | AA17: =IF(OR(W17="",X17=""),"",ROUND((X17-W17)*1440,0)) -> 59 | AB17: =IF(OR(V17="",W17=""),"",ROUND((W17-V17)*1440,0)) -> 15 | AC17: =IF(OR(X17="",Y17=""),"",ROUND((Y17-X17)*1440,0)) -> 12 | AD17: A320 | AF17: RP-C4126 | AG17: RP-C4126 | AH17: N | AI17: S03 | AJ17: CONTACT | AK17: C05 | AL17: REMOTE | AO17: ARRIVED | AP17: ON_BLOCKS | AT17: CURRENT | AW17: =IF(OR(V17="",R17=""),"",ROUND((V17-R17)*1440,0)) -> 4 | AZ17: 156 | BA17: 151 | BB17: 2100 | BC17: 0 | BD17: 0 | BE17: 55400 | BF17: 60745 | BG17: 57345 | BH17: LS-081415 | BI17: 330 | BJ17: 330 | BK17: RPMD | BL17: RPMD | BM17: Y | BN17: N | BO17: Y | BP17: FULL | BQ17: CAR-01 | BR17: N | BS17: Y | BT17: COMPLETE
A18: TC15 | B18: LEG-26081416 | C18: PR | D18: 0150 | E18: 2026-08-17 | F18: 2 | G18: PR | H18: PR | J18: J | K18: REVENUE | L18: MNL | M18: CEB | N18: MNL | O18: CEB | P18: 1 | Q18: N | R18: 46251.667 | S18: 46251.729 | V18: 46251.674 | W18: 46251.685 | X18: 46251.725 | Y18: 46251.733 | Z18: =IF(OR(V18="",Y18=""),"",ROUND((Y18-V18)*1440,0)) -> 85 | AA18: =IF(OR(W18="",X18=""),"",ROUND((X18-W18)*1440,0)) -> 58 | AB18: =IF(OR(V18="",W18=""),"",ROUND((W18-V18)*1440,0)) -> 15 | AC18: =IF(OR(X18="",Y18=""),"",ROUND((Y18-X18)*1440,0)) -> 12 | AD18: A320 | AF18: RP-C4126 | AG18: RP-C4126 | AH18: N | AI18: S03 | AJ18: CONTACT | AK18: C05 | AL18: REMOTE | AO18: ARRIVED | AP18: ON_BLOCKS | AT18: CURRENT | AW18: =IF(OR(V18="",R18=""),"",ROUND((V18-R18)*1440,0)) -> 11 | AZ18: 158 | BA18: 154 | BB18: 2300 | BC18: 0 | BD18: 0 | BE18: 55800 | BF18: 60995 | BG18: 57595 | BH18: LS-081416 | BI18: 330 | BJ18: 330 | BK18: RPMD | BL18: RPMD | BM18: Y | BN18: N | BO18: Y | BP18: FULL | BQ18: CAR-01 | BR18: N | BS18: Y | BT18: COMPLETE
A19: TC16 | B19: LEG-26081417 | C19: PR | D19: 0152 | E19: 2026-08-18 | F19: 1 | G19: PR | H19: PR | J19: J | K19: REVENUE | L19: MNL | M19: SIN | N19: MNL | O19: SIN | P19: 1 | Q19: N | R19: 46252.25 | S19: 46252.41 | V19: 46252.252 | W19: 46252.264 | X19: 46252.401 | Y19: 46252.411 | Z19: =IF(OR(V19="",Y19=""),"",ROUND((Y19-V19)*1440,0)) -> 229 | AA19: =IF(OR(W19="",X19=""),"",ROUND((X19-W19)*1440,0)) -> 198 | AB19: =IF(OR(V19="",W19=""),"",ROUND((W19-V19)*1440,0)) -> 17 | AC19: =IF(OR(X19="",Y19=""),"",ROUND((Y19-X19)*1440,0)) -> 14 | AD19: A321 | AF19: RP-C4128 | AG19: RP-C4128 | AH19: N | AI19: S12 | AJ19: CONTACT | AK19: B04 | AL19: CONTACT | AO19: ARRIVED | AP19: ON_BLOCKS | AT19: CURRENT | AW19: =IF(OR(V19="",R19=""),"",ROUND((V19-R19)*1440,0)) -> 3 | AZ19: 167 | BA19: 163 | BB19: 4200 | BC19: 0 | BD19: 0 | BE19: 68300 | BF19: 79551 | BG19: 71131 | BH19: LS-081417 | BI19: 350 | BJ19: 350 | BK19: WSSS | BL19: WSSS | BM19: Y | BN19: N | BO19: Y | BP19: FULL | BQ19: CAR-01 | BR19: N | BS19: Y | BT19: COMPLETE
A20: TC17 | B20: LEG-26081418 | C20: PR | D20: 0154 | E20: 2026-08-18 | F20: 1 | G20: PR | H20: PR | J20: J | K20: REVENUE | L20: MNL | M20: SIN | N20: MNL | O20: SIN | P20: 1 | Q20: N | R20: 46252.458 | S20: 46252.618 | V20: 46252.476 | W20: 46252.488 | X20: 46252.626 | Y20: 46252.635 | Z20: =IF(OR(V20="",Y20=""),"",ROUND((Y20-V20)*1440,0)) -> 229 | AA20: =IF(OR(W20="",X20=""),"",ROUND((X20-W20)*1440,0)) -> 198 | AB20: =IF(OR(V20="",W20=""),"",ROUND((W20-V20)*1440,0)) -> 17 | AC20: =IF(OR(X20="",Y20=""),"",ROUND((Y20-X20)*1440,0)) -> 14 | AD20: A321 | AF20: RP-C4130 | AG20: RP-C4130 | AH20: N | AI20: S14 | AJ20: CONTACT | AK20: B07 | AL20: CONTACT | AO20: ARRIVED | AP20: ON_BLOCKS | AT20: CURRENT | AW20: =IF(OR(V20="",R20=""),"",ROUND((V20-R20)*1440,0)) -> 26 | AZ20: 173 | BA20: 169 | BB20: 4600 | BC20: 0 | BD20: 0 | BE20: 69000 | BF20: 80251 | BG20: 71131 | BH20: LS-081418 | BI20: 350 | BJ20: 350 | BK20: WSSS | BL20: WSSS | BM20: Y | BN20: N | BO20: Y | BP20: FULL | BQ20: CAR-01 | BR20: N | BS20: N | BT20: COMPLETE
A21: TC18 | B21: LEG-26081419 | C21: PR | D21: 0156 | E21: 2026-08-18 | F21: 1 | G21: PR | H21: PR | J21: J | K21: REVENUE | L21: MNL | M21: SIN | N21: MNL | O21: SIN | P21: 1 | Q21: N | R21: 46252.625 | S21: 46252.785 | V21: 46252.628 | W21: 46252.64 | X21: 46252.781 | Y21: 46252.79 | Z21: =IF(OR(V21="",Y21=""),"",ROUND((Y21-V21)*1440,0)) -> 234 | AA21: =IF(OR(W21="",X21=""),"",ROUND((X21-W21)*1440,0)) -> 203 | AB21: =IF(OR(V21="",W21=""),"",ROUND((W21-V21)*1440,0)) -> 17 | AC21: =IF(OR(X21="",Y21=""),"",ROUND((Y21-X21)*1440,0)) -> 14 | AD21: A321 | AF21: RP-C4132 | AG21: RP-C4132 | AH21: N | AI21: S09 | AJ21: CONTACT | AK21: B02 | AL21: CONTACT | AO21: ARRIVED | AP21: ON_BLOCKS | AT21: CURRENT | AW21: =IF(OR(V21="",R21=""),"",ROUND((V21-R21)*1440,0)) -> 4 | AZ21: 178 | BA21: 175 | BB21: 4900 | BC21: 0 | BD21: 0 | BE21: 70100 | BF21: 81719 | BG21: 71819 | BH21: LS-081419 | BI21: 350 | BJ21: 350 | BK21: WSSS | BL21: WSSS | BM21: Y | BN21: N | BO21: Y | BP21: FULL | BQ21: CAR-01 | BR21: N | BS21: N | BT21: COMPLETE
A22: TC19 | B22: LEG-26081420 | C22: PR | D22: 0158 | E22: 2026-08-19 | F22: 1 | G22: PR | H22: PR | J22: J | K22: REVENUE | L22: MNL | M22: SIN | N22: MNL | O22: SIN | P22: 1 | Q22: N | R22: 46253.25 | S22: 46253.41 | V22: 46253.256 | W22: 46253.268 | X22: 46253.406 | Y22: 46253.415 | Z22: =IF(OR(V22="",Y22=""),"",ROUND((Y22-V22)*1440,0)) -> 229 | AA22: =IF(OR(W22="",X22=""),"",ROUND((X22-W22)*1440,0)) -> 198 | AB22: =IF(OR(V22="",W22=""),"",ROUND((W22-V22)*1440,0)) -> 17 | AC22: =IF(OR(X22="",Y22=""),"",ROUND((Y22-X22)*1440,0)) -> 14 | AD22: A321 | AF22: RP-C4134 | AG22: RP-C4134 | AH22: N | AI22: S12 | AJ22: CONTACT | AK22: B04 | AL22: CONTACT | AO22: ARRIVED | AP22: ON_BLOCKS | AT22: CURRENT | AW22: =IF(OR(V22="",R22=""),"",ROUND((V22-R22)*1440,0)) -> 9 | AZ22: 166 | BA22: 162 | BB22: 4100 | BC22: 0 | BD22: 0 | BE22: 68200 | BF22: 79630 | BG22: 71030 | BH22: LS-081420 | BI22: 350 | BJ22: 350 | BK22: WSSS | BL22: WSSS | BM22: Y | BN22: N | BO22: Y | BP22: FULL | BQ22: CAR-01 | BR22: N | BS22: Y | BT22: COMPLETE
A23: TC20 | B23: LEG-26081421 | C23: PR | D23: 0160 | E23: 2026-08-19 | F23: 1 | G23: PR | H23: PR | J23: J | K23: REVENUE | L23: MNL | M23: SIN | N23: MNL | O23: SIN | P23: 1 | Q23: N | R23: 46253.458 | S23: 46253.618 | V23: 46253.46 | W23: 46253.472 | X23: 46253.609 | Y23: 46253.619 | Z23: =IF(OR(V23="",Y23=""),"",ROUND((Y23-V23)*1440,0)) -> 229 | AA23: =IF(OR(W23="",X23=""),"",ROUND((X23-W23)*1440,0)) -> 198 | AB23: =IF(OR(V23="",W23=""),"",ROUND((W23-V23)*1440,0)) -> 17 | AC23: =IF(OR(X23="",Y23=""),"",ROUND((Y23-X23)*1440,0)) -> 14 | AD23: A321 | AF23: RP-C4136 | AG23: RP-C4136 | AH23: N | AI23: S14 | AJ23: CONTACT | AK23: B07 | AL23: CONTACT | AO23: ARRIVED | AP23: ON_BLOCKS | AT23: CURRENT | AW23: =IF(OR(V23="",R23=""),"",ROUND((V23-R23)*1440,0)) -> 2 | AZ23: 175 | BA23: 172 | BB23: 4700 | BC23: 0 | BD23: 0 | BE23: 69400 | BF23: 81551 | BG23: 71951 | BH23: LS-081421 | BI23: 350 | BJ23: 350 | BK23: WSSS | BL23: WSSS | BM23: Y | BN23: N | BO23: Y | BP23: FULL | BQ23: CAR-01 | BR23: N | BS23: N | BT23: NOT_CAPTURED
A24: TC21 | B24: LEG-26081422 | C24: PR | D24: 0110 | E24: 2026-08-19 | F24: 1 | G24: PR | H24: PR | J24: J | K24: REVENUE | L24: MNL | M24: LAX | N24: MNL | O24: LAX | P24: 1 | Q24: N | R24: 46253.556 | S24: 46254.045 | V24: 46253.557 | W24: 46253.569 | X24: 46254.031 | Y24: 46254.04 | Z24: =IF(OR(V24="",Y24=""),"",ROUND((Y24-V24)*1440,0)) -> 696 | AA24: =IF(OR(W24="",X24=""),"",ROUND((X24-W24)*1440,0)) -> 664 | AB24: =IF(OR(V24="",W24=""),"",ROUND((W24-V24)*1440,0)) -> 18 | AC24: =IF(OR(X24="",Y24=""),"",ROUND((Y24-X24)*1440,0)) -> 14 | AD24: A350-900 | AF24: RP-C3513 | AG24: RP-C3513 | AH24: N | AI24: S22 | AJ24: CONTACT | AK24: T148 | AL24: CONTACT | AO24: ARRIVED | AP24: ON_BLOCKS | AT24: CURRENT | AW24: =IF(OR(V24="",R24=""),"",ROUND((V24-R24)*1440,0)) -> 2 | AZ24: 288 | BA24: 283 | BB24: 18900 | BC24: 0 | BD24: 0 | BE24: 178900 | BF24: 263486 | BG24: 190486 | BH24: LS-081422 | BI24: 340 | BJ24: 360 | BK24: KSFO | BL24: KSFO | BM24: Y | BN24: N | BO24: Y | BP24: FULL | BQ24: CAR-01 | BR24: N | BS24: Y | BT24: COMPLETE
A25: TC22 | B25: LEG-26081423 | C25: PR | D25: 0162 | E25: 2026-08-20 | F25: 1 | G25: PR | H25: PR | J25: J | K25: REVENUE | L25: MNL | M25: SIN | N25: MNL | O25: SIN | P25: 1 | Q25: N | R25: 46254.25 | S25: 46254.41 | V25: 46254.272 | W25: 46254.283 | X25: 46254.421 | Y25: 46254.431 | Z25: =IF(OR(V25="",Y25=""),"",ROUND((Y25-V25)*1440,0)) -> 229 | AA25: =IF(OR(W25="",X25=""),"",ROUND((X25-W25)*1440,0)) -> 198 | AB25: =IF(OR(V25="",W25=""),"",ROUND((W25-V25)*1440,0)) -> 17 | AC25: =IF(OR(X25="",Y25=""),"",ROUND((Y25-X25)*1440,0)) -> 14 | AD25: A321 | AF25: RP-C4138 | AG25: RP-C4138 | AH25: N | AI25: S12 | AJ25: CONTACT | AK25: B04 | AL25: CONTACT | AO25: ARRIVED | AP25: ON_BLOCKS | AT25: CURRENT | AV25: 89 | AW25: =IF(OR(V25="",R25=""),"",ROUND((V25-R25)*1440,0)) -> 31 | AZ25: 164 | BA25: 159 | BB25: 4000 | BC25: 0 | BD25: 0 | BE25: 67900 | BF25: 79151 | BG25: 70701 | BH25: LS-081423 | BI25: 350 | BJ25: 350 | BK25: WSSS | BL25: WSSS | BM25: Y | BN25: N | BO25: Y | BP25: FULL | BQ25: CAR-01 | BR25: N | BS25: N | BT25: PARTIAL
A26: TC33 | B26: LEG-26081424 | C26: PR | D26: 0164 | E26: 2026-08-21 | F26: 1 | G26: PR | H26: PR | J26: J | K26: REVENUE | L26: MNL | M26: SIN | N26: MNL | O26: SIN | P26: 1 | Q26: N | R26: 46255.25 | S26: 46255.41 | V26: 46255.253 | W26: 46255.265 | X26: 46255.403 | Y26: 46255.412 | Z26: =IF(OR(V26="",Y26=""),"",ROUND((Y26-V26)*1440,0)) -> 229 | AA26: =IF(OR(W26="",X26=""),"",ROUND((X26-W26)*1440,0)) -> 198 | AB26: =IF(OR(V26="",W26=""),"",ROUND((W26-V26)*1440,0)) -> 17 | AC26: =IF(OR(X26="",Y26=""),"",ROUND((Y26-X26)*1440,0)) -> 14 | AD26: A321 | AF26: RP-C4140 | AG26: RP-C4140 | AH26: N | AI26: S12 | AJ26: CONTACT | AK26: B04 | AL26: CONTACT | AO26: ARRIVED | AP26: ON_BLOCKS | AT26: CURRENT | AW26: =IF(OR(V26="",R26=""),"",ROUND((V26-R26)*1440,0)) -> 5 | AZ26: 171 | BA26: 168 | BB26: 4500 | BC26: 0 | BD26: 0 | BE26: 68800 | BF26: 83394 | BG26: 71581 | BH26: LS-081424 | BI26: 350 | BJ26: 350 | BK26: WSSS | BL26: WSSS | BM26: Y | BN26: N | BO26: Y | BP26: FULL | BQ26: CAR-01 | BR26: Y | BS26: N | BT26: COMPLETE
A29: FIELD GROUPS - why each group is held
A30: Group | B30: Fields | C30: Purpose in FuelSphere
A31: Identity | B31: carrier codes, flight number, date, leg sequence, service type | C31: Resolves the leg and the carrier arrangement. operating_carrier is distinct from the flight number
A32: OOOI | B32: out, off, on, in | C32: The four points burn is derived between. Without off and on there is no trip or taxi split
A33: Derived times | B33: block, flight, taxi out, taxi in minutes | C33: Ground time drives APU estimation. Taxi time explains taxi burn variance
A34: Stand | B34: dep and arr stand, stand type | C34: Contact versus remote determines whether APU running was avoidable
A35: Weight and payload | B35: ZFW, TOW, LW, pax, cargo | C35: Actual versus planned weight explains most burn variance
A36: Operational | B36: cruise level planned and flown, alternate planned and used | C36: Level and route deviation is the other main variance cause
A37: Efficiency flags | B37: single engine taxi, de-icing, APU reported | C37: Efficiency KPIs and taxi burn context
A38: Fuel linkage | B38: processing mode, arrangement, provisional tail, burn capture status | C38: Stamped at resolution; drives whether fuel is processed at all

Sheet FD_FUEL_PLAN
A1: FD_FUEL_PLAN - PK fd_fuel_plan_id | UK flight_leg_id + plan_version | one row per plan VERSION
A2: TC_ID | B2: fd_fuel_plan_id | C2: flight_leg_id | D2: plan_group_id | E2: plan_version | F2: source_system | G2: ofp_reference | H2: registration | I2: fuel_unit | J2: trip_fuel | K2: contingency_fuel | L2: alternate_fuel | M2: final_reserve_fuel | N2: additional_fuel | O2: taxi_fuel | P2: extra_fuel | Q2: block_fuel | R2: fuel_on_board | S2: required_uplift | T2: tankering_flag | U2: extra_reason_code | V2: plan_status | W2: change_reason | X2: fuelling_state_at_change | Y2: received_utc
A3: TC01 | B3: FDP-0101 | C3: LEG-26081401 | D3: PLG-101 | E3: 1 | F3: LIDO | G3: PR126/14AUG/01 | H3: RP-C4108 | I3: KG | J3: 8420 | K3: 421 | L3: 1180 | M3: 1050 | N3: 0 | O3: 180 | P3: 0 | Q3: =SUM(J3:P3) -> 11251 | R3: 2100 | S3: =Q3-R3 -> 9151 | T3: N | V3: ACTIVE | X3: NOT_STARTED | Y3: 2026-08-14T02:14Z
A4: TC02 | B4: FDP-0201 | C4: LEG-26081402 | D4: PLG-201 | E4: 1 | F4: LIDO | G4: PR128/14AUG/01 | H4: RP-C4110 | I4: KG | J4: 8420 | K4: 421 | L4: 1180 | M4: 1050 | N4: 0 | O4: 180 | P4: 0 | Q4: =SUM(J4:P4) -> 11251 | R4: 2050 | S4: =Q4-R4 -> 9201 | T4: N | V4: SUPERSEDED | X4: NOT_STARTED | Y4: 2026-08-14T07:10Z
A5: TC02 | B5: FDP-0202 | C5: LEG-26081402 | D5: PLG-201 | E5: 2 | F5: LIDO | G5: PR128/14AUG/02 | H5: RP-C4110 | I5: KG | J5: 8690 | K5: 435 | L5: 1180 | M5: 1050 | N5: 0 | O5: 180 | P5: 0 | Q5: =SUM(J5:P5) -> 11535 | R5: 2050 | S5: =Q5-R5 -> 9485 | T5: N | V5: ACTIVE | W5: PAYLOAD_INCREASE | X5: NOT_STARTED | Y5: 2026-08-14T08:05Z
A6: TC03 | B6: FDP-0301 | C6: LEG-26081403 | D6: PLG-301 | E6: 1 | F6: LIDO | G6: PR130/14AUG/01 | H6: RP-C4112 | I6: KG | J6: 8420 | K6: 421 | L6: 1180 | M6: 1050 | N6: 0 | O6: 180 | P6: 0 | Q6: =SUM(J6:P6) -> 11251 | R6: 2100 | S6: =Q6-R6 -> 9151 | T6: N | V6: SUPERSEDED | X6: NOT_STARTED | Y6: 2026-08-14T11:00Z
A7: TC03 | B7: FDP-0302 | C7: LEG-26081403 | D7: PLG-301 | E7: 2 | F7: LIDO | G7: PR130/14AUG/02 | H7: RP-C4112 | I7: KG | J7: 9140 | K7: 457 | L7: 1180 | M7: 1050 | N7: 0 | O7: 260 | P7: 200 | Q7: =SUM(J7:P7) -> 12287 | R7: 11540 | S7: =Q7-R7 -> 747 | T7: N | U7: OPS | V7: ACTIVE | W7: ATC_REROUTE | X7: COMPLETED | Y7: 2026-08-14T13:22Z
A8: TC04 | B8: FDP-0401 | C8: LEG-26081404 | D8: PLG-401 | E8: 1 | F8: LIDO | G8: PR132/14AUG/01 | H8: RP-C4108 | I8: KG | J8: 8420 | K8: 421 | L8: 1180 | M8: 1050 | N8: 0 | O8: 180 | P8: 0 | Q8: =SUM(J8:P8) -> 11251 | R8: 2100 | S8: =Q8-R8 -> 9151 | T8: N | V8: SUPERSEDED | X8: COMPLETED | Y8: 2026-08-14T14:00Z
A9: TC04 | B9: FDP-0402 | C9: LEG-26081404 | D9: PLG-401 | E9: 2 | F9: LIDO | G9: PR132/14AUG/02 | H9: RP-C4109 | I9: KG | J9: 8510 | K9: 426 | L9: 1180 | M9: 1050 | N9: 0 | O9: 180 | P9: 0 | Q9: =SUM(J9:P9) -> 11346 | R9: 4900 | S9: =Q9-R9 -> 6446 | T9: N | V9: ACTIVE | W9: TAIL_SWAP | X9: COMPLETED | Y9: 2026-08-14T16:38Z
A10: TC05 | B10: FDP-0501 | C10: LEG-26081405 | D10: PLG-501 | E10: 1 | F10: LIDO | G10: PR102/14AUG/01 | H10: RP-C3505 | I10: KG | J10: 96400 | K10: 2892 | L10: 3100 | M10: 2400 | N10: 0 | O10: 600 | P10: 0 | Q10: =SUM(J10:P10) -> 105392 | R10: 5200 | S10: =Q10-R10 -> 100192 | T10: N | V10: ACTIVE | X10: NOT_STARTED | Y10: 2026-08-14T09:10Z
A11: TC06 | B11: FDP-0601 | C11: LEG-26081406 | D11: PLG-601 | E11: 1 | F11: LIDO | G11: PR104/15AUG/01 | H11: RP-C3507 | I11: KG | J11: 96400 | K11: 2892 | L11: 3100 | M11: 2400 | N11: 0 | O11: 600 | P11: 0 | Q11: =SUM(J11:P11) -> 105392 | R11: 5200 | S11: =Q11-R11 -> 100192 | T11: N | V11: SUPERSEDED | X11: NOT_STARTED | Y11: 2026-08-15T09:10Z
A12: TC06 | B12: FDP-0602 | C12: LEG-26081406 | D12: PLG-601 | E12: 2 | F12: LIDO | G12: PR104/15AUG/02 | H12: RP-C3507 | I12: KG | J12: 96400 | K12: 2892 | L12: 5850 | M12: 2400 | N12: 0 | O12: 600 | P12: 0 | Q12: =SUM(J12:P12) -> 108142 | R12: 69594 | S12: =Q12-R12 -> 38548 | T12: N | V12: ACTIVE | W12: ALTERNATE_CHANGE | X12: IN_PROGRESS | Y12: 2026-08-15T11:48Z
A13: TC07 | B13: FDP-0701 | C13: LEG-26081407 | D13: PLG-701 | E13: 1 | F13: LIDO | G13: PR134/15AUG/01 | H13: RP-C4114 | I13: KG | J13: 8420 | K13: 421 | L13: 1180 | M13: 1050 | N13: 0 | O13: 180 | P13: 0 | Q13: =SUM(J13:P13) -> 11251 | R13: 2100 | S13: =Q13-R13 -> 9151 | T13: N | V13: CANCELLED | W13: FLIGHT_CANCELLED | X13: COMPLETED | Y13: 2026-08-15T02:20Z
A14: TC08 | B14: FDP-0801 | C14: LEG-26081408 | D14: PLG-801 | E14: 1 | F14: LIDO | G14: PR136/15AUG/01 | H14: RP-C4116 | I14: KG | J14: 8420 | K14: 421 | L14: 1180 | M14: 1050 | N14: 0 | O14: 180 | P14: 0 | Q14: =SUM(J14:P14) -> 11251 | R14: 2100 | S14: =Q14-R14 -> 9151 | T14: N | V14: SUPERSEDED | X14: COMPLETED | Y14: 2026-08-15T07:10Z
A15: TC08 | B15: FDP-0802 | C15: LEG-26081408 | D15: PLG-801 | E15: 2 | F15: LIDO | G15: PR136/15AUG/02 | H15: RP-C4116 | I15: KG | J15: 6900 | K15: 345 | L15: 1180 | M15: 1050 | N15: 0 | O15: 180 | P15: 0 | Q15: =SUM(J15:P15) -> 9655 | R15: 11251 | S15: =Q15-R15 -> -1596 | T15: N | V15: ACTIVE | W15: RETURN_TO_RAMP | X15: COMPLETED | Y15: 2026-08-15T11:40Z
A16: TC09 | B16: FDP-0901 | C16: LEG-26081409 | D16: PLG-901 | E16: 1 | F16: LIDO | G16: PR106/15AUG/01 | H16: RP-C3509 | I16: KG | J16: 96400 | K16: 2892 | L16: 3100 | M16: 2400 | N16: 0 | O16: 600 | P16: 0 | Q16: =SUM(J16:P16) -> 105392 | R16: 5200 | S16: =Q16-R16 -> 100192 | T16: N | V16: ACTIVE | X16: COMPLETED | Y16: 2026-08-15T09:10Z
A17: TC10 | B17: FDP-1001 | C17: LEG-26081410 | D17: PLG-1001 | E17: 1 | F17: LIDO | G17: PR138/16AUG/01 | H17: RP-C4118 | I17: KG | J17: 8420 | K17: 421 | L17: 1180 | M17: 1050 | N17: 0 | O17: 180 | P17: 0 | Q17: =SUM(J17:P17) -> 11251 | R17: 2100 | S17: =Q17-R17 -> 9151 | T17: N | V17: ACTIVE | X17: NOT_STARTED | Y17: 2026-08-16T02:14Z
A18: TC11 | B18: FDP-1101 | C18: LEG-26081411 | D18: PLG-1101 | E18: 1 | F18: LIDO | G18: PR140/16AUG/01 | H18: RP-C4120 | I18: KG | J18: 8420 | K18: 421 | L18: 1180 | M18: 1050 | N18: 0 | O18: 180 | P18: 0 | Q18: =SUM(J18:P18) -> 11251 | R18: 2100 | S18: =Q18-R18 -> 9151 | T18: N | V18: SUPERSEDED | X18: NOT_STARTED | Y18: 2026-08-16T07:00Z
A19: TC11 | B19: FDP-1102 | C19: LEG-26081411 | D19: PLG-1101 | E19: 2 | F19: LIDO | G19: PR140/16AUG/02 | H19: RP-C4120 | I19: KG | J19: 8420 | K19: 421 | L19: 1180 | M19: 1050 | N19: 0 | O19: 180 | P19: 900 | Q19: =SUM(J19:P19) -> 12151 | R19: 2100 | S19: =Q19-R19 -> 10051 | T19: N | U19: CMD_WX_HOLDING | V19: ACTIVE | W19: CAPTAIN_REQUEST | X19: NOT_STARTED | Y19: 2026-08-16T08:15Z
A20: TC12 | B20: FDP-1201 | C20: LEG-26081412 | D20: PLG-1201 | E20: 1 | F20: LIDO | G20: PR142/16AUG/01 | H20: RP-C4122 | I20: KG | J20: 8420 | K20: 421 | L20: 1180 | M20: 1050 | N20: 0 | O20: 180 | P20: 0 | Q20: =SUM(J20:P20) -> 11251 | R20: 2100 | S20: =Q20-R20 -> 9151 | T20: N | V20: ACTIVE | X20: NOT_STARTED | Y20: 2026-08-16T11:00Z
A21: TC13 | B21: FDP-1301 | C21: LEG-26081413 | D21: PLG-1301 | E21: 1 | F21: LIDO | G21: PR108/16AUG/01 | H21: RP-C3511 | I21: KG | J21: 96400 | K21: 2892 | L21: 3100 | M21: 2400 | N21: 0 | O21: 600 | P21: 0 | Q21: =SUM(J21:P21) -> 105392 | R21: 5200 | S21: =Q21-R21 -> 100192 | T21: N | V21: ACTIVE | X21: NOT_STARTED | Y21: 2026-08-16T09:10Z
A22: TC14 | B22: FDP-1401 | C22: LEG-26081414 | D22: PLG-1401 | E22: 1 | F22: LIDO | G22: PR144/17AUG/01 | H22: RP-C4124 | I22: KG | J22: 8420 | K22: 421 | L22: 1180 | M22: 1050 | N22: 0 | O22: 180 | P22: 3200 | Q22: =SUM(J22:P22) -> 14451 | R22: 2100 | S22: =Q22-R22 -> 12351 | T22: Y | U22: TANKERING | V22: ACTIVE | X22: NOT_STARTED | Y22: 2026-08-17T02:14Z
A23: TC15 | B23: FDP-1501 | C23: LEG-26081415 | D23: PLG-1501 | E23: 1 | F23: LIDO | G23: PR150/17AUG/01 | H23: RP-C4126 | I23: KG | J23: 3100 | K23: 155 | L23: 900 | M23: 1050 | N23: 0 | O23: 140 | P23: 0 | Q23: =SUM(J23:P23) -> 5345 | R23: 1800 | S23: =Q23-R23 -> 3545 | T23: N | V23: ACTIVE | X23: NOT_STARTED | Y23: 2026-08-17T02:00Z
A24: TC15 | B24: FDP-1601 | C24: LEG-26081416 | D24: PLG-1601 | E24: 1 | F24: LIDO | G24: PR150/17AUG/03 | H24: RP-C4126 | I24: KG | J24: 3100 | K24: 155 | L24: 900 | M24: 1050 | N24: 0 | O24: 140 | P24: 0 | Q24: =SUM(J24:P24) -> 5345 | R24: 1650 | S24: =Q24-R24 -> 3695 | T24: N | V24: ACTIVE | X24: NOT_STARTED | Y24: 2026-08-17T11:00Z
A25: TC16 | B25: FDP-1701 | C25: LEG-26081417 | D25: PLG-1701 | E25: 1 | F25: LIDO | G25: PR152/18AUG/01 | H25: RP-C4128 | I25: KG | J25: 8420 | K25: 421 | L25: 1180 | M25: 1050 | N25: 0 | O25: 180 | P25: 0 | Q25: =SUM(J25:P25) -> 11251 | R25: 2100 | S25: =Q25-R25 -> 9151 | T25: N | V25: ACTIVE | X25: NOT_STARTED | Y25: 2026-08-18T02:14Z
A26: TC17 | B26: FDP-1801 | C26: LEG-26081418 | D26: PLG-1801 | E26: 1 | F26: LIDO | G26: PR154/18AUG/01 | H26: RP-C4130 | I26: KG | J26: 8420 | K26: 421 | L26: 1180 | M26: 1050 | N26: 0 | O26: 180 | P26: 0 | Q26: =SUM(J26:P26) -> 11251 | R26: 2100 | S26: =Q26-R26 -> 9151 | T26: N | V26: ACTIVE | X26: NOT_STARTED | Y26: 2026-08-18T07:10Z
A27: TC18 | B27: FDP-1901 | C27: LEG-26081419 | D27: PLG-1901 | E27: 1 | F27: LIDO | G27: PR156/18AUG/01 | H27: RP-C4132 | I27: KG | J27: 8770 | K27: 439 | L27: 1180 | M27: 1050 | N27: 0 | O27: 180 | P27: 0 | Q27: =SUM(J27:P27) -> 11619 | R27: 2100 | S27: =Q27-R27 -> 9519 | T27: N | V27: ACTIVE | X27: NOT_STARTED | Y27: 2026-08-18T11:00Z
A28: TC19 | B28: FDP-2001 | C28: LEG-26081420 | D28: PLG-2001 | E28: 1 | F28: LIDO | G28: PR158/19AUG/01 | H28: RP-C4134 | I28: KG | J28: 8420 | K28: 421 | L28: 1180 | M28: 1050 | N28: 0 | O28: 180 | P28: 0 | Q28: =SUM(J28:P28) -> 11251 | R28: 11000 | S28: =Q28-R28 -> 251 | T28: N | V28: ACTIVE | W28: SLOT_DELAY | X28: COMPLETED | Y28: 2026-08-19T04:40Z
A29: TC20 | B29: FDP-2101 | C29: LEG-26081421 | D29: PLG-2101 | E29: 1 | F29: LIDO | G29: PR160/19AUG/01 | H29: RP-C4136 | I29: KG | J29: 8420 | K29: 421 | L29: 1180 | M29: 1050 | N29: 0 | O29: 180 | P29: 0 | Q29: =SUM(J29:P29) -> 11251 | R29: 2100 | S29: =Q29-R29 -> 9151 | T29: N | V29: ACTIVE | X29: NOT_STARTED | Y29: 2026-08-19T07:10Z
A30: TC21 | B30: FDP-2201 | C30: LEG-26081422 | D30: PLG-2201 | E30: 1 | F30: LIDO | G30: PR110/19AUG/01 | H30: RP-C3513 | I30: KG | J30: 76200 | K30: 2286 | L30: 3100 | M30: 2400 | N30: 0 | O30: 600 | P30: 0 | Q30: =SUM(J30:P30) -> 84586 | R30: 5200 | S30: =Q30-R30 -> 79386 | T30: N | V30: ACTIVE | X30: NOT_STARTED | Y30: 2026-08-19T09:10Z
A31: TC22 | B31: FDP-2301 | C31: LEG-26081423 | D31: PLG-2301 | E31: 1 | F31: LIDO | G31: PR162/20AUG/01 | H31: RP-C4138 | I31: KG | J31: 8420 | K31: 421 | L31: 1180 | M31: 1050 | N31: 0 | O31: 180 | P31: 0 | Q31: =SUM(J31:P31) -> 11251 | R31: 2100 | S31: =Q31-R31 -> 9151 | T31: N | V31: ACTIVE | X31: NOT_STARTED | Y31: 2026-08-20T02:14Z
A32: TC33 | B32: FDP-2401 | C32: LEG-26081424 | D32: PLG-2401 | E32: 1 | F32: LIDO | G32: PR164/21AUG/01 | H32: RP-C4140 | I32: KG | J32: 8420 | K32: 421 | L32: 1180 | M32: 1050 | N32: 0 | O32: 180 | P32: 0 | Q32: =SUM(J32:P32) -> 11251 | R32: 2100 | S32: =Q32-R32 -> 9151 | T32: N | V32: ACTIVE | X32: NOT_STARTED | Y32: 2026-08-21T02:14Z

Sheet FUEL_ORDER
A1: FUEL_ORDER - PK fuel_order_id | UK order_number + order_version | delivered_qty summed from tickets; fulfilment checked at order level
A2: TC_ID | B2: fuel_order_id | C2: order_number | D2: order_version | E2: flight_leg_id | F2: fd_fuel_plan_id | G2: registration | H2: station | I2: supplier_code | J2: ordered_qty | K2: order_unit | L2: order_type | M2: delivered_qty | N2: ticket_count | O2: variance_qty | P2: variance_pct | Q2: tolerance_qty | R2: fulfilment_check | S2: order_status | T2: under_delivery_reason | U2: freeze_flag | V2: sent_utc
A3: TC01 | B3: ORD-1001 | C3: PR/MNL/140826/0126 | D3: 1 | E3: LEG-26081401 | F3: FDP-0101 | G3: RP-C4108 | H3: MNL | I3: PPC | J3: 9151 | K3: KG | L3: INITIAL | M3: =SUMIFS(FUEL_TICKET!$Z:$Z,FUEL_TICKET!$I:$I,$B3) -> 9151.1 | N3: =COUNTIFS(FUEL_TICKET!$I:$I,$B3) -> 1 | O3: =ROUND(M3-J3,1) -> 0.1 | P3: =IF(J3=0,"",O3/ABS(J3)) -> 1.0927767e-05 | Q3: =MAX(50,0.01*ABS(J3)) -> 91.51 | R3: =IF(S3="SUPERSEDED","NOT_APPLICABLE",IF(N3=0,"NOT_DELIVERED",IF(ABS(O3)<=Q3,"WITHIN_TOLERANCE",IF(O3<0,"UNDER_DELIVERED","OVER_DELIVERED")))) -> WITHIN_TOLERANCE | S3: FULFILLED | U3: Y | V3: 2026-08-14T02:30Z
A4: TC02 | B4: ORD-1002 | C4: PR/MNL/140826/0128 | D4: 1 | E4: LEG-26081402 | F4: FDP-0201 | G4: RP-C4110 | H4: MNL | I4: PPC | J4: 9201 | K4: KG | L4: INITIAL | M4: =SUMIFS(FUEL_TICKET!$Z:$Z,FUEL_TICKET!$I:$I,$B4) -> 0 | N4: =COUNTIFS(FUEL_TICKET!$I:$I,$B4) -> 0 | O4: =ROUND(M4-J4,1) -> -9201 | P4: =IF(J4=0,"",O4/ABS(J4)) -> -1 | Q4: =MAX(50,0.01*ABS(J4)) -> 92.01 | R4: =IF(S4="SUPERSEDED","NOT_APPLICABLE",IF(N4=0,"NOT_DELIVERED",IF(ABS(O4)<=Q4,"WITHIN_TOLERANCE",IF(O4<0,"UNDER_DELIVERED","OVER_DELIVERED")))) -> NOT_APPLICABLE | S4: SUPERSEDED | U4: N | V4: 2026-08-14T07:25Z
A5: TC02 | B5: ORD-1003 | C5: PR/MNL/140826/0128 | D5: 2 | E5: LEG-26081402 | F5: FDP-0202 | G5: RP-C4110 | H5: MNL | I5: PPC | J5: 9485 | K5: KG | L5: AMENDMENT | M5: =SUMIFS(FUEL_TICKET!$Z:$Z,FUEL_TICKET!$I:$I,$B5) -> 9485.3 | N5: =COUNTIFS(FUEL_TICKET!$I:$I,$B5) -> 1 | O5: =ROUND(M5-J5,1) -> 0.3 | P5: =IF(J5=0,"",O5/ABS(J5)) -> 3.1628888e-05 | Q5: =MAX(50,0.01*ABS(J5)) -> 94.85 | R5: =IF(S5="SUPERSEDED","NOT_APPLICABLE",IF(N5=0,"NOT_DELIVERED",IF(ABS(O5)<=Q5,"WITHIN_TOLERANCE",IF(O5<0,"UNDER_DELIVERED","OVER_DELIVERED")))) -> WITHIN_TOLERANCE | S5: FULFILLED | U5: Y | V5: 2026-08-14T08:20Z
A6: TC03 | B6: ORD-1004 | C6: PR/MNL/140826/0130 | D6: 1 | E6: LEG-26081403 | F6: FDP-0301 | G6: RP-C4112 | H6: MNL | I6: PPC | J6: 9151 | K6: KG | L6: INITIAL | M6: =SUMIFS(FUEL_TICKET!$Z:$Z,FUEL_TICKET!$I:$I,$B6) -> 9151.9 | N6: =COUNTIFS(FUEL_TICKET!$I:$I,$B6) -> 1 | O6: =ROUND(M6-J6,1) -> 0.9 | P6: =IF(J6=0,"",O6/ABS(J6)) -> 9.8349907e-05 | Q6: =MAX(50,0.01*ABS(J6)) -> 91.51 | R6: =IF(S6="SUPERSEDED","NOT_APPLICABLE",IF(N6=0,"NOT_DELIVERED",IF(ABS(O6)<=Q6,"WITHIN_TOLERANCE",IF(O6<0,"UNDER_DELIVERED","OVER_DELIVERED")))) -> WITHIN_TOLERANCE | S6: FULFILLED | U6: Y | V6: 2026-08-14T11:15Z
A7: TC03 | B7: ORD-1005 | C7: PR/MNL/140826/0130-T | D7: 1 | E7: LEG-26081403 | F7: FDP-0302 | G7: RP-C4112 | H7: MNL | I7: PPC | J7: 747 | K7: KG | L7: TOP_UP | M7: =SUMIFS(FUEL_TICKET!$Z:$Z,FUEL_TICKET!$I:$I,$B7) -> 746.7 | N7: =COUNTIFS(FUEL_TICKET!$I:$I,$B7) -> 1 | O7: =ROUND(M7-J7,1) -> -0.3 | P7: =IF(J7=0,"",O7/ABS(J7)) -> -0.00040160643 | Q7: =MAX(50,0.01*ABS(J7)) -> 50 | R7: =IF(S7="SUPERSEDED","NOT_APPLICABLE",IF(N7=0,"NOT_DELIVERED",IF(ABS(O7)<=Q7,"WITHIN_TOLERANCE",IF(O7<0,"UNDER_DELIVERED","OVER_DELIVERED")))) -> WITHIN_TOLERANCE | S7: FULFILLED | U7: Y | V7: 2026-08-14T13:30Z
A8: TC04 | B8: ORD-1006 | C8: PR/MNL/140826/0132 | D8: 1 | E8: LEG-26081404 | F8: FDP-0401 | G8: RP-C4108 | H8: MNL | I8: PPC | J8: 9151 | K8: KG | L8: INITIAL | M8: =SUMIFS(FUEL_TICKET!$Z:$Z,FUEL_TICKET!$I:$I,$B8) -> 9151.9 | N8: =COUNTIFS(FUEL_TICKET!$I:$I,$B8) -> 1 | O8: =ROUND(M8-J8,1) -> 0.9 | P8: =IF(J8=0,"",O8/ABS(J8)) -> 9.8349907e-05 | Q8: =MAX(50,0.01*ABS(J8)) -> 91.51 | R8: =IF(S8="SUPERSEDED","NOT_APPLICABLE",IF(N8=0,"NOT_DELIVERED",IF(ABS(O8)<=Q8,"WITHIN_TOLERANCE",IF(O8<0,"UNDER_DELIVERED","OVER_DELIVERED")))) -> WITHIN_TOLERANCE | S8: FULFILLED | U8: Y | V8: 2026-08-14T14:15Z
A9: TC04 | B9: ORD-1007 | C9: PR/MNL/140826/0132-S | D9: 1 | E9: LEG-26081404 | F9: FDP-0402 | G9: RP-C4109 | H9: MNL | I9: PPC | J9: 6446 | K9: KG | L9: INITIAL | M9: =SUMIFS(FUEL_TICKET!$Z:$Z,FUEL_TICKET!$I:$I,$B9) -> 6445.6 | N9: =COUNTIFS(FUEL_TICKET!$I:$I,$B9) -> 1 | O9: =ROUND(M9-J9,1) -> -0.4 | P9: =IF(J9=0,"",O9/ABS(J9)) -> -6.2053987e-05 | Q9: =MAX(50,0.01*ABS(J9)) -> 64.46 | R9: =IF(S9="SUPERSEDED","NOT_APPLICABLE",IF(N9=0,"NOT_DELIVERED",IF(ABS(O9)<=Q9,"WITHIN_TOLERANCE",IF(O9<0,"UNDER_DELIVERED","OVER_DELIVERED")))) -> WITHIN_TOLERANCE | S9: FULFILLED | U9: Y | V9: 2026-08-14T16:50Z
A10: TC05 | B10: ORD-1008 | C10: PR/MNL/140826/0102 | D10: 1 | E10: LEG-26081405 | F10: FDP-0501 | G10: RP-C3505 | H10: MNL | I10: PPC | J10: 100192 | K10: KG | L10: INITIAL | M10: =SUMIFS(FUEL_TICKET!$Z:$Z,FUEL_TICKET!$I:$I,$B10) -> 100191.7 | N10: =COUNTIFS(FUEL_TICKET!$I:$I,$B10) -> 2 | O10: =ROUND(M10-J10,1) -> -0.3 | P10: =IF(J10=0,"",O10/ABS(J10)) -> -2.994251e-06 | Q10: =MAX(50,0.01*ABS(J10)) -> 1001.92 | R10: =IF(S10="SUPERSEDED","NOT_APPLICABLE",IF(N10=0,"NOT_DELIVERED",IF(ABS(O10)<=Q10,"WITHIN_TOLERANCE",IF(O10<0,"UNDER_DELIVERED","OVER_DELIVERED")))) -> WITHIN_TOLERANCE | S10: FULFILLED | U10: Y | V10: 2026-08-14T09:25Z
A11: TC06 | B11: ORD-1009 | C11: PR/MNL/150826/0104 | D11: 1 | E11: LEG-26081406 | F11: FDP-0601 | G11: RP-C3507 | H11: MNL | I11: PPC | J11: 100192 | K11: KG | L11: INITIAL | M11: =SUMIFS(FUEL_TICKET!$Z:$Z,FUEL_TICKET!$I:$I,$B11) -> 64394 | N11: =COUNTIFS(FUEL_TICKET!$I:$I,$B11) -> 2 | O11: =ROUND(M11-J11,1) -> -35798 | P11: =IF(J11=0,"",O11/ABS(J11)) -> -0.357294 | Q11: =MAX(50,0.01*ABS(J11)) -> 1001.92 | R11: =IF(S11="SUPERSEDED","NOT_APPLICABLE",IF(N11=0,"NOT_DELIVERED",IF(ABS(O11)<=Q11,"WITHIN_TOLERANCE",IF(O11<0,"UNDER_DELIVERED","OVER_DELIVERED")))) -> UNDER_DELIVERED | S11: PART_FULFILLED | T11: FUELLING_INTERRUPTED_BY_REPLAN | U11: Y | V11: 2026-08-15T09:25Z
A12: TC06 | B12: ORD-1010 | C12: PR/MNL/150826/0104-T | D12: 1 | E12: LEG-26081406 | F12: FDP-0602 | G12: RP-C3507 | H12: MNL | I12: PPC | J12: 38548 | K12: KG | L12: TOP_UP | M12: =SUMIFS(FUEL_TICKET!$Z:$Z,FUEL_TICKET!$I:$I,$B12) -> 38548.3 | N12: =COUNTIFS(FUEL_TICKET!$I:$I,$B12) -> 1 | O12: =ROUND(M12-J12,1) -> 0.3 | P12: =IF(J12=0,"",O12/ABS(J12)) -> 7.7825049e-06 | Q12: =MAX(50,0.01*ABS(J12)) -> 385.48 | R12: =IF(S12="SUPERSEDED","NOT_APPLICABLE",IF(N12=0,"NOT_DELIVERED",IF(ABS(O12)<=Q12,"WITHIN_TOLERANCE",IF(O12<0,"UNDER_DELIVERED","OVER_DELIVERED")))) -> WITHIN_TOLERANCE | S12: FULFILLED | U12: Y | V12: 2026-08-15T11:55Z
A13: TC07 | B13: ORD-1011 | C13: PR/MNL/150826/0134 | D13: 1 | E13: LEG-26081407 | F13: FDP-0701 | G13: RP-C4114 | H13: MNL | I13: PPC | J13: 9151 | K13: KG | L13: INITIAL | M13: =SUMIFS(FUEL_TICKET!$Z:$Z,FUEL_TICKET!$I:$I,$B13) -> 9151.9 | N13: =COUNTIFS(FUEL_TICKET!$I:$I,$B13) -> 1 | O13: =ROUND(M13-J13,1) -> 0.9 | P13: =IF(J13=0,"",O13/ABS(J13)) -> 9.8349907e-05 | Q13: =MAX(50,0.01*ABS(J13)) -> 91.51 | R13: =IF(S13="SUPERSEDED","NOT_APPLICABLE",IF(N13=0,"NOT_DELIVERED",IF(ABS(O13)<=Q13,"WITHIN_TOLERANCE",IF(O13<0,"UNDER_DELIVERED","OVER_DELIVERED")))) -> WITHIN_TOLERANCE | S13: FULFILLED | U13: Y | V13: 2026-08-15T02:35Z
A14: TC08 | B14: ORD-1012 | C14: PR/MNL/150826/0136 | D14: 1 | E14: LEG-26081408 | F14: FDP-0801 | G14: RP-C4116 | H14: MNL | I14: PPC | J14: 9151 | K14: KG | L14: INITIAL | M14: =SUMIFS(FUEL_TICKET!$Z:$Z,FUEL_TICKET!$I:$I,$B14) -> 9151.9 | N14: =COUNTIFS(FUEL_TICKET!$I:$I,$B14) -> 1 | O14: =ROUND(M14-J14,1) -> 0.9 | P14: =IF(J14=0,"",O14/ABS(J14)) -> 9.8349907e-05 | Q14: =MAX(50,0.01*ABS(J14)) -> 91.51 | R14: =IF(S14="SUPERSEDED","NOT_APPLICABLE",IF(N14=0,"NOT_DELIVERED",IF(ABS(O14)<=Q14,"WITHIN_TOLERANCE",IF(O14<0,"UNDER_DELIVERED","OVER_DELIVERED")))) -> WITHIN_TOLERANCE | S14: FULFILLED | U14: Y | V14: 2026-08-15T07:25Z
A15: TC08 | B15: ORD-1013 | C15: PR/MNL/150826/0136-D | D15: 1 | E15: LEG-26081408 | F15: FDP-0802 | G15: RP-C4116 | H15: MNL | I15: PPC | J15: -1596 | K15: KG | L15: DEFUEL | M15: =SUMIFS(FUEL_TICKET!$Z:$Z,FUEL_TICKET!$I:$I,$B15) -> -1595.8 | N15: =COUNTIFS(FUEL_TICKET!$I:$I,$B15) -> 1 | O15: =ROUND(M15-J15,1) -> 0.2 | P15: =IF(J15=0,"",O15/ABS(J15)) -> 0.00012531328 | Q15: =MAX(50,0.01*ABS(J15)) -> 50 | R15: =IF(S15="SUPERSEDED","NOT_APPLICABLE",IF(N15=0,"NOT_DELIVERED",IF(ABS(O15)<=Q15,"WITHIN_TOLERANCE",IF(O15<0,"UNDER_DELIVERED","OVER_DELIVERED")))) -> WITHIN_TOLERANCE | S15: FULFILLED | U15: Y | V15: 2026-08-15T11:50Z
A16: TC09 | B16: ORD-1014 | C16: PR/MNL/150826/0106 | D16: 1 | E16: LEG-26081409 | F16: FDP-0901 | G16: RP-C3509 | H16: MNL | I16: PPC | J16: 100192 | K16: KG | L16: INITIAL | M16: =SUMIFS(FUEL_TICKET!$Z:$Z,FUEL_TICKET!$I:$I,$B16) -> 100168.5 | N16: =COUNTIFS(FUEL_TICKET!$I:$I,$B16) -> 1 | O16: =ROUND(M16-J16,1) -> -23.5 | P16: =IF(J16=0,"",O16/ABS(J16)) -> -0.00023454966 | Q16: =MAX(50,0.01*ABS(J16)) -> 1001.92 | R16: =IF(S16="SUPERSEDED","NOT_APPLICABLE",IF(N16=0,"NOT_DELIVERED",IF(ABS(O16)<=Q16,"WITHIN_TOLERANCE",IF(O16<0,"UNDER_DELIVERED","OVER_DELIVERED")))) -> WITHIN_TOLERANCE | S16: FULFILLED | U16: Y | V16: 2026-08-15T09:25Z
A17: TC11 | B17: ORD-1015 | C17: PR/MNL/160826/0140 | D17: 1 | E17: LEG-26081411 | F17: FDP-1102 | G17: RP-C4120 | H17: MNL | I17: PPC | J17: 10051 | K17: KG | L17: INITIAL | M17: =SUMIFS(FUEL_TICKET!$Z:$Z,FUEL_TICKET!$I:$I,$B17) -> 10050.5 | N17: =COUNTIFS(FUEL_TICKET!$I:$I,$B17) -> 1 | O17: =ROUND(M17-J17,1) -> -0.5 | P17: =IF(J17=0,"",O17/ABS(J17)) -> -4.9746294e-05 | Q17: =MAX(50,0.01*ABS(J17)) -> 100.51 | R17: =IF(S17="SUPERSEDED","NOT_APPLICABLE",IF(N17=0,"NOT_DELIVERED",IF(ABS(O17)<=Q17,"WITHIN_TOLERANCE",IF(O17<0,"UNDER_DELIVERED","OVER_DELIVERED")))) -> WITHIN_TOLERANCE | S17: FULFILLED | U17: Y | V17: 2026-08-16T08:30Z
A18: TC12 | B18: ORD-1016 | C18: PR/MNL/160826/0142 | D18: 1 | E18: LEG-26081412 | F18: FDP-1201 | G18: RP-C4122 | H18: MNL | I18: PPC | J18: 9151 | K18: KG | L18: INITIAL | M18: =SUMIFS(FUEL_TICKET!$Z:$Z,FUEL_TICKET!$I:$I,$B18) -> 9152.8 | N18: =COUNTIFS(FUEL_TICKET!$I:$I,$B18) -> 1 | O18: =ROUND(M18-J18,1) -> 1.8 | P18: =IF(J18=0,"",O18/ABS(J18)) -> 0.00019669981 | Q18: =MAX(50,0.01*ABS(J18)) -> 91.51 | R18: =IF(S18="SUPERSEDED","NOT_APPLICABLE",IF(N18=0,"NOT_DELIVERED",IF(ABS(O18)<=Q18,"WITHIN_TOLERANCE",IF(O18<0,"UNDER_DELIVERED","OVER_DELIVERED")))) -> WITHIN_TOLERANCE | S18: FULFILLED | U18: Y | V18: 2026-08-16T11:15Z
A19: TC13 | B19: ORD-1017 | C19: PR/MNL/160826/0108 | D19: 1 | E19: LEG-26081413 | F19: FDP-1301 | G19: RP-C3511 | H19: MNL | I19: PPC | J19: 100192 | K19: KG | L19: INITIAL | M19: =SUMIFS(FUEL_TICKET!$Z:$Z,FUEL_TICKET!$I:$I,$B19) -> 100171.7 | N19: =COUNTIFS(FUEL_TICKET!$I:$I,$B19) -> 1 | O19: =ROUND(M19-J19,1) -> -20.3 | P19: =IF(J19=0,"",O19/ABS(J19)) -> -0.00020261099 | Q19: =MAX(50,0.01*ABS(J19)) -> 1001.92 | R19: =IF(S19="SUPERSEDED","NOT_APPLICABLE",IF(N19=0,"NOT_DELIVERED",IF(ABS(O19)<=Q19,"WITHIN_TOLERANCE",IF(O19<0,"UNDER_DELIVERED","OVER_DELIVERED")))) -> WITHIN_TOLERANCE | S19: FULFILLED | U19: Y | V19: 2026-08-16T09:25Z
A20: TC14 | B20: ORD-1018 | C20: PR/MNL/170826/0144 | D20: 1 | E20: LEG-26081414 | F20: FDP-1401 | G20: RP-C4124 | H20: MNL | I20: PPC | J20: 12351 | K20: KG | L20: INITIAL | M20: =SUMIFS(FUEL_TICKET!$Z:$Z,FUEL_TICKET!$I:$I,$B20) -> 12350.7 | N20: =COUNTIFS(FUEL_TICKET!$I:$I,$B20) -> 1 | O20: =ROUND(M20-J20,1) -> -0.3 | P20: =IF(J20=0,"",O20/ABS(J20)) -> -2.4289531e-05 | Q20: =MAX(50,0.01*ABS(J20)) -> 123.51 | R20: =IF(S20="SUPERSEDED","NOT_APPLICABLE",IF(N20=0,"NOT_DELIVERED",IF(ABS(O20)<=Q20,"WITHIN_TOLERANCE",IF(O20<0,"UNDER_DELIVERED","OVER_DELIVERED")))) -> WITHIN_TOLERANCE | S20: FULFILLED | U20: Y | V20: 2026-08-17T02:30Z
A21: TC15 | B21: ORD-1019 | C21: PR/MNL/170826/0150-L1 | D21: 1 | E21: LEG-26081415 | F21: FDP-1501 | G21: RP-C4126 | H21: MNL | I21: PPC | J21: 3545 | K21: KG | L21: INITIAL | M21: =SUMIFS(FUEL_TICKET!$Z:$Z,FUEL_TICKET!$I:$I,$B21) -> 3545 | N21: =COUNTIFS(FUEL_TICKET!$I:$I,$B21) -> 1 | O21: =ROUND(M21-J21,1) -> 0 | P21: =IF(J21=0,"",O21/ABS(J21)) -> 0 | Q21: =MAX(50,0.01*ABS(J21)) -> 50 | R21: =IF(S21="SUPERSEDED","NOT_APPLICABLE",IF(N21=0,"NOT_DELIVERED",IF(ABS(O21)<=Q21,"WITHIN_TOLERANCE",IF(O21<0,"UNDER_DELIVERED","OVER_DELIVERED")))) -> WITHIN_TOLERANCE | S21: FULFILLED | U21: Y | V21: 2026-08-17T02:20Z
A22: TC15 | B22: ORD-1020 | C22: PR/MNL/170826/0150-L2 | D22: 1 | E22: LEG-26081416 | F22: FDP-1601 | G22: RP-C4126 | H22: MNL | I22: PPC | J22: 3695 | K22: KG | L22: INITIAL | M22: =SUMIFS(FUEL_TICKET!$Z:$Z,FUEL_TICKET!$I:$I,$B22) -> 3695.3 | N22: =COUNTIFS(FUEL_TICKET!$I:$I,$B22) -> 1 | O22: =ROUND(M22-J22,1) -> 0.3 | P22: =IF(J22=0,"",O22/ABS(J22)) -> 8.1190798e-05 | Q22: =MAX(50,0.01*ABS(J22)) -> 50 | R22: =IF(S22="SUPERSEDED","NOT_APPLICABLE",IF(N22=0,"NOT_DELIVERED",IF(ABS(O22)<=Q22,"WITHIN_TOLERANCE",IF(O22<0,"UNDER_DELIVERED","OVER_DELIVERED")))) -> WITHIN_TOLERANCE | S22: FULFILLED | U22: Y | V22: 2026-08-17T11:20Z
A23: TC16 | B23: ORD-1021 | C23: PR/MNL/180826/0152 | D23: 1 | E23: LEG-26081417 | F23: FDP-1701 | G23: RP-C4128 | H23: MNL | I23: PPC | J23: 9151 | K23: KG | L23: INITIAL | M23: =SUMIFS(FUEL_TICKET!$Z:$Z,FUEL_TICKET!$I:$I,$B23) -> 9151.9 | N23: =COUNTIFS(FUEL_TICKET!$I:$I,$B23) -> 1 | O23: =ROUND(M23-J23,1) -> 0.9 | P23: =IF(J23=0,"",O23/ABS(J23)) -> 9.8349907e-05 | Q23: =MAX(50,0.01*ABS(J23)) -> 91.51 | R23: =IF(S23="SUPERSEDED","NOT_APPLICABLE",IF(N23=0,"NOT_DELIVERED",IF(ABS(O23)<=Q23,"WITHIN_TOLERANCE",IF(O23<0,"UNDER_DELIVERED","OVER_DELIVERED")))) -> WITHIN_TOLERANCE | S23: FULFILLED | U23: Y | V23: 2026-08-18T02:30Z
... A30: TC33 | B30: ORD-1028 | C30: PR/MNL/210826/0164 | D30: 1 | E30: LEG-26081424 | F30: FDP-2401 | G30: RP-C4140 | H30: MNL | I30: PPC | J30: 9151 | K30: KG | L30: INITIAL | M30: =SUMIFS(FUEL_TICKET!$Z:$Z,FUEL_TICKET!$I:$I,$B30) -> 9594 | N30: =COUNTIFS(FUEL_TICKET!$I:$I,$B30) -> 1 | O30: =ROUND(M30-J30,1) -> 443 | P30: =IF(J30=0,"",O30/ABS(J30)) -> 0.04841001 | Q30: =MAX(50,0.01*ABS(J30)) -> 91.51 | R30: =IF(S30="SUPERSEDED","NOT_APPLICABLE",IF(N30=0,"NOT_DELIVERED",IF(ABS(O30)<=Q30,"WITHIN_TOLERANCE",IF(O30<0,"UNDER_DELIVERED","OVER_DELIVERED")))) -> OVER_DELIVERED | S30: FULFILLED | U30: Y | V30: 2026-08-21T02:30Z

Sheet FUEL_TICKET
A1: FUEL_TICKET (fuel event) - PK ticket_id | UK supplier_code + station + supplier_ticket_no + uplift_date | order and plan FKs are NULLABLE
A2: TC_ID | B2: ticket_id | C2: supplier_code | D2: into_plane_agent_code | E2: station | F2: supplier_ticket_no | G2: uplift_date | H2: flight_leg_id | I2: fuel_order_id | J2: fd_fuel_plan_id | K2: registration | L2: event_type | M2: uplift_sequence | N2: is_partial | O2: fuel_grade | P2: saf_blend_pct | Q2: delivery_method | R2: bowser_id | S2: meter_start | T2: meter_end | U2: quantity_litres | V2: density_kg_per_l | W2: density_temp_c | X2: batch_coa_ref | Y2: quantity_kg_manual | Z2: quantity_kg | AA2: fob_before_kg | AB2: fob_after_kg | AC2: fob_delta_kg | AD2: recon_variance_kg | AE2: recon_status | AF2: water_check_result | AG2: uplift_start_utc | AH2: uplift_end_utc | AI2: fueller_id | AJ2: receiver_signature_ref | AK2: match_status | AL2: cost_allocation_basis | AM2: ticket_source | AN2: raw_payload_ref | AO2: created_by | AP2: created_utc | AQ2: changed_by | AR2: changed_utc | AS2: notes
A3: TC01 | B3: TK-2001 | C3: PPC | D3: PPC-IPA | E3: MNL | F3: 880101 | G3: 2026-08-14 | H3: LEG-26081401 | I3: ORD-1001 | J3: FDP-0101 | K3: RP-C4108 | L3: UPLIFT | M3: 1 | N3: N | O3: JET_A1 | P3: 0 | Q3: HYDRANT | R3: BW-11 | S3: 12000 | T3: 23446 | U3: 11446 | V3: 0.7995 | W3: 30.5 | X3: COA-PPC-8000 | Z3: =IF(U3="",Y3,ROUND(U3*V3,1)) -> 9151.1 | AA3: 2100 | AB3: 11251 | AC3: =IF(OR(AA3="",AB3=""),"",AB3-AA3) -> 9151 | AD3: =IF(AC3="","",ROUND(Z3-AC3,1)) -> 0.1 | AE3: =IF(AC3="","NOT_RECONCILED",IF(ABS(AD3)<=MAX(50,0.02*ABS(Z3)),"PASS","FAIL")) -> PASS | AF3: PASS | AG3: 2026-08-14T03:40:00Z | AH3: 2026-08-14T04:05:00Z | AI3: FL-100 | AJ3: SIG-880101 | AK3: MATCHED | AL3: FLIGHT_LEG | AM3: EDI | AN3: RAW-T9000 | AO3: IF_INTERFACE | AP3: 2026-08-14T2026-08-14T03:40:00ZZ | AS3: Baseline single uplift
A4: TC02 | B4: TK-2002 | C4: PPC | D4: PPC-IPA | E4: MNL | F4: 880115 | G4: 2026-08-14 | H4: LEG-26081402 | I4: ORD-1003 | J4: FDP-0202 | K4: RP-C4110 | L4: UPLIFT | M4: 1 | N4: N | O4: JET_A1 | P4: 0 | Q4: HYDRANT | R4: BW-11 | S4: 23446 | T4: 35310 | U4: 11864 | V4: 0.7995 | W4: 30.5 | X4: COA-PPC-8001 | Z4: =IF(U4="",Y4,ROUND(U4*V4,1)) -> 9485.3 | AA4: 2050 | AB4: 11535 | AC4: =IF(OR(AA4="",AB4=""),"",AB4-AA4) -> 9485 | AD4: =IF(AC4="","",ROUND(Z4-AC4,1)) -> 0.3 | AE4: =IF(AC4="","NOT_RECONCILED",IF(ABS(AD4)<=MAX(50,0.02*ABS(Z4)),"PASS","FAIL")) -> PASS | AF4: PASS | AG4: 2026-08-14T09:10:00Z | AH4: 2026-08-14T09:36:00Z | AI4: FL-101 | AJ4: SIG-880115 | AK4: MATCHED | AL4: FLIGHT_LEG | AM4: EDI | AN4: RAW-T9001 | AO4: IF_INTERFACE | AP4: 2026-08-14T2026-08-14T09:10:00ZZ | AS4: Uplift against amended order v2
